<?xml version="1.0"?>
<!-- created with Phobos 1.0.1 "Capricious Choutengan" -->
  <robot name="od">

    <link name="link_hip_a">
      <inertial>
        <origin xyz="0 0 0" rpy="0 0 0"/>
        <mass value="0.15"/>
        <inertia ixx="4e-05" ixy="0" ixz="0" iyy="0.00041" iyz="0" izz="0.00041"/>
      </inertial>
      <visual name="visual_Hip_Fe_Module_A">
        <origin xyz="0 0 0" rpy="0 0 0"/>
        <geometry>
          <mesh filename="HipFeModuleA.dae" scale="1.0 1.0 1.0"/>
        </geometry>
        <material name="Material"/>
      </visual>
      <collision name="collision_hip_a">
        <origin xyz="0 0 0" rpy="0 0 0"/>
        <geometry>
          <box size="0.1759 0.0389 0.04438"/>
        </geometry>
      </collision>
    </link>

    <link name="link_hip_b">
      <inertial>
        <origin xyz="0 0 0" rpy="0 0 0"/>
        <mass value="0.15"/>
        <inertia ixx="4e-05" ixy="0" ixz="0" iyy="0.00053" iyz="0" izz="0.00052"/>
      </inertial>
      <visual name="visual_Hip_Adapter_B">
        <origin xyz="0 0 0" rpy="0 0 0"/>
        <geometry>
          <mesh filename="HipAdapterB.dae" scale="1.0 1.0 1.0"/>
        </geometry>
        <material name="Material"/>
      </visual>
      <visual name="visual_Hip_Fe_Module_B">
        <origin xyz="0 0 0" rpy="0 0 0"/>
        <geometry>
          <mesh filename="HipFeModuleB.dae" scale="1.0 1.0 1.0"/>
        </geometry>
        <material name="Material"/>
      </visual>
      <collision name="Hip Fe Module B">
        <origin xyz="0 0 0" rpy="0 0 0"/>
        <geometry>
          <box size="0.201 0.0389 0.04438"/>
        </geometry>
      </collision>
    </link>

    <link name="link_hip_c">
      <inertial>
        <origin xyz="0 0 0" rpy="0 0 0"/>
        <mass value="0.15"/>
        <inertia ixx="4e-05" ixy="0" ixz="0" iyy="0.00053" iyz="0" izz="0.00052"/>
      </inertial>
      <visual name="visual_HipFeModuleC">
        <origin xyz="0 0 0" rpy="0 0 0"/>
        <geometry>
          <mesh filename="HipFeModuleC.dae" scale="1.0 1.0 1.0"/>
        </geometry>
        <material name="Material"/>
      </visual>
      <visual name="visual_Hip_Adapter_C">
        <origin xyz="0 0 0" rpy="0 0 0"/>
        <geometry>
          <mesh filename="HipAdapterC.dae" scale="1.0 1.0 1.0"/>
        </geometry>
        <material name="Material"/>
      </visual>
      <collision name="Hip Fe Module B">
        <origin xyz="0 0 0" rpy="0 0 0"/>
        <geometry>
          <box size="0.201 0.0389 0.04438"/>
        </geometry>
      </collision>
    </link>

    <link name="link_hip_d">
      <inertial>
        <origin xyz="0 0 0" rpy="0 0 0"/>
        <mass value="0.15"/>
        <inertia ixx="4e-05" ixy="0" ixz="0" iyy="0.00041" iyz="0" izz="0.00041"/>
      </inertial>
      <visual name="visual_Hip_Fe_Module_D">
        <origin xyz="0 0 0" rpy="0 0 0"/>
        <geometry>
          <mesh filename="HipFeModuleD.dae" scale="1.0 1.0 1.0"/>
        </geometry>
        <material name="Material"/>
      </visual>
      <collision name="Hip Fe Module A">
        <origin xyz="0 0 0" rpy="0 0 0"/>
        <geometry>
          <box size="0.1759 0.0389 0.04438"/>
        </geometry>
      </collision>
    </link>

    <link name="link_l_leg_a">
      <inertial>
        <origin xyz="0 0 0" rpy="0 0 0"/>
        <mass value="0.02"/>
        <inertia ixx="4e-05" ixy="0" ixz="0" iyy="6e-05" iyz="0" izz="3e-05"/>
      </inertial>
      <visual name="visual_Lower_Leg_A">
        <origin xyz="0.09277 0.14695 0.12354" rpy="0 0 0"/>
        <geometry>
          <mesh filename="LowerLegA.dae" scale="1.0 1.0 1.0"/>
        </geometry>
        <material name="Material"/>
      </visual>
      <collision name="collision_Cyl_link_l_leg_a">
        <origin xyz="0 0 0" rpy="0 0 0"/>
        <geometry>
          <cylinder radius="0.0165" length="0.033"/>
        </geometry>
      </collision>
      <collision name="collision_Lower_Leg">
        <origin xyz="0.09277 0.14695 0.12354" rpy="0 0 0"/>
        <geometry>
          <mesh filename="col_LowerLegA.dae" scale="1.0 1.0 1.0"/>
        </geometry>
      </collision>
    </link>

    <link name="link_l_leg_b">
      <inertial>
        <origin xyz="0 0 0" rpy="0 0 0"/>
        <mass value="0.02"/>
        <inertia ixx="4e-05" ixy="0" ixz="0" iyy="6e-05" iyz="0" izz="3e-05"/>
      </inertial>
      <visual name="visual_Lower_Leg_B">
        <origin xyz="0 0 0" rpy="0 0 0"/>
        <geometry>
          <mesh filename="LowerLegB.dae" scale="1.0 1.0 1.0"/>
        </geometry>
        <material name="Material"/>
      </visual>
      <collision name="Cylinder">
        <origin xyz="0 0 0" rpy="0 0 0"/>
        <geometry>
          <cylinder radius="0.0165" length="0.033"/>
        </geometry>
      </collision>
      <collision name="collision_Lower_Leg_B">
        <origin xyz="0 0 0" rpy="0 0 0"/>
        <geometry>
          <mesh filename="col_LowerLegB.dae" scale="1.0 1.0 1.0"/>
        </geometry>
      </collision>
    </link>

    <link name="link_l_leg_c">
      <inertial>
        <origin xyz="0 0 0" rpy="0 0 0"/>
        <mass value="0.02"/>
        <inertia ixx="4e-05" ixy="0" ixz="0" iyy="6e-05" iyz="0" izz="3e-05"/>
      </inertial>
      <visual name="visual_Lower_Leg_C">
        <origin xyz="0 0 0" rpy="0 0 0"/>
        <geometry>
          <mesh filename="LowerLegC.dae" scale="1.0 1.0 1.0"/>
        </geometry>
        <material name="Material"/>
      </visual>
      <collision name="collision_Cylinder.003">
        <origin xyz="0 0 0" rpy="0 0 0"/>
        <geometry>
          <cylinder radius="0.0165" length="0.033"/>
        </geometry>
      </collision>
      <collision name="collision_Lower_Leg_C">
        <origin xyz="0 0 0" rpy="0 0 0"/>
        <geometry>
          <mesh filename="col_LowerLegC.dae" scale="1.0 1.0 1.0"/>
        </geometry>
      </collision>
    </link>

    <link name="link_l_leg_d">
      <inertial>
        <origin xyz="0 0 0" rpy="0 0 0"/>
        <mass value="0.02"/>
        <inertia ixx="4e-05" ixy="0" ixz="0" iyy="6e-05" iyz="0" izz="3e-05"/>
      </inertial>
      <visual name="visual_Lower_Leg_D">
        <origin xyz="0 0 0" rpy="0 0 0"/>
        <geometry>
          <mesh filename="LowerLegD.dae" scale="1.0 1.0 1.0"/>
        </geometry>
        <material name="Material"/>
      </visual>
      <collision name="Cylinder.001">
        <origin xyz="0 0 0" rpy="0 0 0"/>
        <geometry>
          <cylinder radius="0.0165" length="0.033"/>
        </geometry>
      </collision>
      <collision name="collision_Lower_Leg_D">
        <origin xyz="0 0 0" rpy="0 0 0"/>
        <geometry>
          <mesh filename="col_LowerLegD.dae" scale="1.0 1.0 1.0"/>
        </geometry>
      </collision>
    </link>

    <link name="link_root">
      <inertial>
        <origin xyz="0 0 0.3" rpy="0 0 0"/>
        <mass value="1.2"/>
        <inertia ixx="0.00125" ixy="0" ixz="0" iyy="0.01546" iyz="0" izz="0.01621"/>
      </inertial>
      <visual name="visual_Body_Structure">
        <origin xyz="0 0 0.3" rpy="0 0 0"/>
        <geometry>
          <mesh filename="Body_Structure.dae" scale="1.0 1.0 1.0"/>
        </geometry>
        <material name="Material"/>
      </visual>
      <visual name="visual_Hip_Aa_Module_A">
        <origin xyz="0 0 0.3" rpy="0 0 0"/>
        <geometry>
          <mesh filename="HipAaModuleA.dae" scale="1.0 1.0 1.0"/>
        </geometry>
        <material name="Material"/>
      </visual>
      <visual name="visual_Hip_Aa_Module_B">
        <origin xyz="0 0 0.3" rpy="0 0 0"/>
        <geometry>
          <mesh filename="HipAaModuleB.dae" scale="1.0 1.0 1.0"/>
        </geometry>
        <material name="Material"/>
      </visual>
      <visual name="visual_Hip_Aa_Module_C">
        <origin xyz="0 0 0.3" rpy="0 0 0"/>
        <geometry>
          <mesh filename="HipAaModuleC.dae" scale="1.0 1.0 1.0"/>
        </geometry>
        <material name="Material"/>
      </visual>
      <visual name="visual_Hip_Aa_Module_D">
        <origin xyz="0 0 0.3" rpy="0 0 0"/>
        <geometry>
          <mesh filename="HipAaModuleD.dae" scale="1.0 1.0 1.0"/>
        </geometry>
        <material name="Material"/>
      </visual>
      <collision name="collision_root">
        <origin xyz="0 0 0.3" rpy="0 0 0"/>
        <geometry>
          <box size="0.39 0.1 0.05"/>
        </geometry>
      </collision>
      <collision name="collision_root_0">
        <origin xyz="0 0 0.3" rpy="0 0 0"/>
        <geometry>
          <box size="0.01 0.04 0.04"/>
        </geometry>
      </collision>
      <collision name="collision_root_1">
        <origin xyz="0 0 0.3" rpy="0 0 0"/>
        <geometry>
          <box size="0.01 0.04 0.04"/>
        </geometry>
      </collision>
      <collision name="collision_root_2">
        <origin xyz="0 0 0.3" rpy="0 0 0"/>
        <geometry>
          <box size="0.01 0.04 0.04"/>
        </geometry>
      </collision>
      <collision name="collision_root_3">
        <origin xyz="0 0 0.3" rpy="0 0 0"/>
        <geometry>
          <box size="0.01 0.04 0.04"/>
        </geometry>
      </collision>
    </link>

    <link name="link_u_leg_a">
      <inertial>
        <origin xyz="0 0 0" rpy="0 0 0"/>
        <mass value="0.15"/>
        <inertia ixx="0.00015" ixy="0" ixz="0.00011" iyy="0.00025" iyz="0" izz="0.00011"/>
      </inertial>
      <visual name="visual_Upper_Leg_Module_A">
        <origin xyz="0 0 0" rpy="0 0 0"/>
        <geometry>
          <mesh filename="UpperLegModuleA.dae" scale="1.0 1.0 1.0"/>
        </geometry>
        <material name="Material"/>
      </visual>
      <collision name="Upper Leg Module">
        <origin xyz="0 0 0" rpy="0 0 0"/>
        <geometry>
          <box size="0.11331 0.014 0.12771"/>
        </geometry>
      </collision>
      <collision name="collision_Cylinder.001">
        <origin xyz="0 -0.001 0" rpy="0 0 0"/>
        <geometry>
          <cylinder radius="0.0175" length="0.035"/>
        </geometry>
      </collision>
      <collision name="collision_cyl_a">
        <origin xyz="0 0.001 0" rpy="0 0 0"/>
        <geometry>
          <cylinder radius="0.0175" length="0.035"/>
        </geometry>
      </collision>
    </link>

    <link name="link_u_leg_b">
      <inertial>
        <origin xyz="0 0 0" rpy="0 0 0"/>
        <mass value="0.15"/>
        <inertia ixx="0.00015" ixy="0" ixz="0.00011" iyy="0.00025" iyz="0" izz="0.00011"/>
      </inertial>
      <visual name="visual_upper_leg_b">
        <origin xyz="0 0 0" rpy="0 0 0"/>
        <geometry>
          <mesh filename="UpperLegModuleB.dae" scale="1.0 1.0 1.0"/>
        </geometry>
        <material name="Material"/>
      </visual>
      <collision name="Upper Leg Module">
        <origin xyz="0 0 0" rpy="0 0 0"/>
        <geometry>
          <box size="0.11331 0.014 0.12771"/>
        </geometry>
      </collision>
      <collision name="collision_Cylinder.006">
        <origin xyz="0 -0.001 0" rpy="0 0 0"/>
        <geometry>
          <cylinder radius="0.0175" length="0.035"/>
        </geometry>
      </collision>
      <collision name="collision_Cylinder.007">
        <origin xyz="0 0.001 0" rpy="0 0 0"/>
        <geometry>
          <cylinder radius="0.0175" length="0.035"/>
        </geometry>
      </collision>
    </link>

    <link name="link_u_leg_c">
      <inertial>
        <origin xyz="0 0 0" rpy="0 0 0"/>
        <mass value="0.15"/>
        <inertia ixx="0.00015" ixy="0" ixz="-0.00011" iyy="0.00025" iyz="0" izz="0.00011"/>
      </inertial>
      <visual name="visual_Upper_Leg_Module_C">
        <origin xyz="0 0 0" rpy="0 0 0"/>
        <geometry>
          <mesh filename="UpperLegModuleC.dae" scale="1.0 1.0 1.0"/>
        </geometry>
        <material name="Material"/>
      </visual>
      <collision name="Upper Leg Module">
        <origin xyz="0 0 0" rpy="0 0 0"/>
        <geometry>
          <box size="0.11331 0.014 0.12771"/>
        </geometry>
      </collision>
      <collision name="collision_Cylinder.008">
        <origin xyz="0 -0.006 0" rpy="0 0 0"/>
        <geometry>
          <cylinder radius="0.0175" length="0.035"/>
        </geometry>
      </collision>
      <collision name="collision_Cylinder.009">
        <origin xyz="0 0 0" rpy="0 0 0"/>
        <geometry>
          <cylinder radius="0.0175" length="0.035"/>
        </geometry>
      </collision>
    </link>

    <link name="link_u_leg_d">
      <inertial>
        <origin xyz="0.00016 0.00015 9e-05" rpy="0 0 0"/>
        <mass value="0.15"/>
        <inertia ixx="0.00015" ixy="0" ixz="-0.00011" iyy="0.00025" iyz="0" izz="0.00011"/>
      </inertial>
      <visual name="visual_Upper_Leg_Module_D">
        <origin xyz="0.00016 0.00015 9e-05" rpy="0 0 0"/>
        <geometry>
          <mesh filename="UpperLegModuleD.dae" scale="1.0 1.0 1.0"/>
        </geometry>
        <material name="Material"/>
      </visual>
      <collision name="Upper Leg Module">
        <origin xyz="0.00016 0.00015 9e-05" rpy="0 0 0"/>
        <geometry>
          <box size="0.11331 0.014 0.12771"/>
        </geometry>
      </collision>
      <collision name="collision_Cylinder.010">
        <origin xyz="0.00016 0 9e-05" rpy="0 0 0"/>
        <geometry>
          <cylinder radius="0.0175" length="0.035"/>
        </geometry>
      </collision>
      <collision name="collision_Cylinder.011">
        <origin xyz="0.00016 0.002 9e-05" rpy="0 0 0"/>
        <geometry>
          <cylinder radius="0.0175" length="0.035"/>
        </geometry>
      </collision>
    </link>

    <joint name="link_hip_a" type="revolute">
      <origin xyz="-0.1939 -0.09 0.3" rpy="0 0 0"/>
      <parent link="link_root"/>
      <child link="link_hip_a"/>
      <axis xyz="-1.0 0 0"/>
      <limit lower="-1.31" upper="2.443" effort="2.7" velocity="50.0"/>
    </joint>

    <joint name="link_hip_b" type="revolute">
      <origin xyz="-0.1939 0.09 0.3" rpy="0 0 0"/>
      <parent link="link_root"/>
      <child link="link_hip_b"/>
      <axis xyz="-1.0 0 0"/>
      <limit lower="-1.31" upper="2.443" effort="2.7" velocity="50.0"/>
    </joint>

    <joint name="link_hip_c" type="revolute">
      <origin xyz="0.1939 -0.09 0.3" rpy="0 0 0"/>
      <parent link="link_root"/>
      <child link="link_hip_c"/>
      <axis xyz="1.0 0 0"/>
      <limit lower="-1.31" upper="2.443" effort="2.7" velocity="50.0"/>
    </joint>

    <joint name="link_hip_d" type="revolute">
      <origin xyz="0.1939 0.09 0.3" rpy="0 0 0"/>
      <parent link="link_root"/>
      <child link="link_hip_d"/>
      <axis xyz="1.0 0 0"/>
      <limit lower="-1.31" upper="2.443" effort="2.7" velocity="50.0"/>
    </joint>

    <joint name="link_l_leg_a" type="revolute">
      <origin xyz="0.10113 -0.05695 -0.12354" rpy="0 -2.83267 0"/>
      <parent link="link_u_leg_a"/>
      <child link="link_l_leg_a"/>
      <axis xyz="0 -1.0 0"/>
      <limit lower="-6.3" upper="6.3" effort="2.7" velocity="50.0"/>
    </joint>

    <joint name="link_l_leg_b" type="revolute">
      <origin xyz="0.10113 0.05695 -0.12354" rpy="0 -2.82743 0"/>
      <parent link="link_u_leg_b"/>
      <child link="link_l_leg_b"/>
      <axis xyz="0 1.0 0"/>
      <limit lower="-6.3" upper="6.3" effort="2.7" velocity="50.0"/>
    </joint>

    <joint name="link_l_leg_c" type="revolute">
      <origin xyz="-0.10113 -0.05695 -0.12354" rpy="0 0 0"/>
      <parent link="link_u_leg_c"/>
      <child link="link_l_leg_c"/>
      <axis xyz="0 -1.0 0"/>
      <limit lower="-6.3" upper="6.3" effort="2.7" velocity="50.0"/>
    </joint>

    <joint name="link_l_leg_d" type="revolute">
      <origin xyz="-0.10112 0.05695 -0.12354" rpy="0 0 0"/>
      <parent link="link_u_leg_d"/>
      <child link="link_l_leg_d"/>
      <axis xyz="0 1.0 0"/>
      <limit lower="-1.31" upper="2.443" effort="2.7" velocity="50.0"/>
    </joint>

    <joint name="link_u_leg_a" type="revolute">
      <origin xyz="0 0 0" rpy="0 1.37881 0"/>
      <parent link="link_hip_a"/>
      <child link="link_u_leg_a"/>
      <axis xyz="0 -1.0 0"/>
      <limit lower="-6.3" upper="6.3" effort="2.7" velocity="50.0"/>
    </joint>

    <joint name="link_u_leg_b" type="revolute">
      <origin xyz="0 0 0" rpy="0 1.37881 0"/>
      <parent link="link_hip_b"/>
      <child link="link_u_leg_b"/>
      <axis xyz="0 1.0 0"/>
      <limit lower="-6.3" upper="6.3" effort="2.7" velocity="50.0"/>
    </joint>

    <joint name="link_u_leg_c" type="revolute">
      <origin xyz="0 0 0" rpy="0 0 0"/>
      <parent link="link_hip_c"/>
      <child link="link_u_leg_c"/>
      <axis xyz="0 -1.0 0"/>
      <limit lower="-6.3" upper="6.3" effort="2.7" velocity="50.0"/>
    </joint>

    <joint name="link_u_leg_d" type="revolute">
      <origin xyz="0 0 0" rpy="0 0 0"/>
      <parent link="link_hip_d"/>
      <child link="link_u_leg_d"/>
      <axis xyz="0 1.0 0"/>
      <limit lower="-6.3" upper="6.3" effort="2.7" velocity="50.0"/>
    </joint>

    <material name="Material">
      <color rgba="0.64 0.57001 0.34995 1.0"/>
    </material>

  </robot>
