<?xml version="1.0"?>
<!-- created with Phobos 1.0.1 "Capricious Choutengan" -->
  <robot name="od">

    <link name="link_hip_a">
      <inertial>
        <origin xyz="0 0 0" rpy="0 0 0"/>
        <mass value="0.15"/>
        <inertia ixx="4e-05" ixy="0" ixz="0" iyy="0.00041" iyz="0" izz="0.00041"/>
      </inertial>
      <visual name="visual_Hip_Fe_Module_A">
        <origin xyz="0 0 0" rpy="0 0 0"/>
        <geometry>
          <mesh filename="HipFeModuleA.stl" scale="1.0 1.0 1.0"/>
        </geometry>
        <material name="Material"/>
      </visual>
      <collision name="collision_hip_a">
        <origin xyz="0 0.001 0" rpy="0 0 0"/>
        <geometry>
          <mesh filename="collision_HipA.stl" scale="1.0 0.9 1.0"/>
        </geometry>
      </collision>
    </link>

    <link name="link_hip_b">
      <inertial>
        <origin xyz="0 0 0" rpy="0 0 0"/>
        <mass value="0.15"/>
        <inertia ixx="4e-05" ixy="0" ixz="0" iyy="0.00053" iyz="0" izz="0.00052"/>
      </inertial>
      <visual name="visual_Hip_Adapter_B">
        <origin xyz="0 0 0" rpy="0 0 0"/>
        <geometry>
          <mesh filename="HipAdapterB.stl" scale="1.0 1.0 1.0"/>
        </geometry>
        <material name="Material"/>
      </visual>
      <visual name="visual_Hip_Fe_Module_B">
        <origin xyz="0 0 0" rpy="0 0 0"/>
        <geometry>
          <mesh filename="HipFeModuleB.stl" scale="1.0 1.0 1.0"/>
        </geometry>
        <material name="Material"/>
      </visual>
      <collision name="Hip Fe Module B">
        <origin xyz="0 0 0" rpy="0 0 0"/>
        <geometry>
          <mesh filename="collision_HipB.stl" scale="1.0 0.9 1.0"/>
        </geometry>
      </collision>
    </link>

    <link name="link_hip_c">
      <inertial>
        <origin xyz="0 0 0" rpy="0 0 0"/>
        <mass value="0.15"/>
        <inertia ixx="4e-05" ixy="0" ixz="0" iyy="0.00053" iyz="0" izz="0.00052"/>
      </inertial>
      <visual name="visual_HipFeModuleC">
        <origin xyz="0 0 0" rpy="0 0 0"/>
        <geometry>
          <mesh filename="HipFeModuleC.stl" scale="1.0 1.0 1.0"/>
        </geometry>
        <material name="Material"/>
      </visual>
      <visual name="visual_Hip_Adapter_C">
        <origin xyz="0 0 0" rpy="0 0 0"/>
        <geometry>
          <mesh filename="HipAdapterC.stl" scale="1.0 1.0 1.0"/>
        </geometry>
        <material name="Material"/>
      </visual>
      <collision name="Hip Fe Module B">
        <origin xyz="0 0 0" rpy="0 0 0"/>
        <geometry>
          <mesh filename="collision_HipC.stl" scale="1.0 1.0 1.0"/>
        </geometry>
      </collision>
    </link>

    <link name="link_hip_d">
      <inertial>
        <origin xyz="0 0 0" rpy="0 0 0"/>
        <mass value="0.15"/>
        <inertia ixx="4e-05" ixy="0" ixz="0" iyy="0.00041" iyz="0" izz="0.00041"/>
      </inertial>
      <visual name="visual_Hip_Fe_Module_D">
        <origin xyz="0 0 0" rpy="0 0 0"/>
        <geometry>
          <mesh filename="HipFeModuleD.stl" scale="1.0 1.0 1.0"/>
        </geometry>
        <material name="Material"/>
      </visual>
      <collision name="Hip Fe Module A">
        <origin xyz="0 0 0" rpy="0 0 0"/>
        <geometry>
          <mesh filename="collision_HipD.stl" scale="1.0 1.0 1.0"/>
        </geometry>
      </collision>
    </link>

    <link name="link_l_leg_a">
      <inertial>
        <origin xyz="0 0 0" rpy="0 0 0"/>
        <mass value="0.02"/>
        <inertia ixx="4e-05" ixy="0" ixz="0" iyy="6e-05" iyz="0" izz="3e-05"/>
      </inertial>
      <visual name="visual_Lower_Leg_A">
        <origin xyz="-0.00085 0.00212 7e-05" rpy="0 0 0"/>
        <geometry>
          <mesh filename="LowerLegA.stl" scale="1.0 1.0 1.0"/>
        </geometry>
        <material name="Material"/>
      </visual>
      <collision name="collision_Lower_Leg_A">
        <origin xyz="-0.00085 0.00212 7e-05" rpy="0 0 0"/>
        <geometry>
          <mesh filename="collision_LowerLegA.stl" scale="1.0 1.0 1.0"/>
        </geometry>
      </collision>
    </link>

    <link name="link_l_leg_b">
      <inertial>
        <origin xyz="0 0 0" rpy="0 0 0"/>
        <mass value="0.02"/>
        <inertia ixx="4e-05" ixy="0" ixz="0" iyy="6e-05" iyz="0" izz="3e-05"/>
      </inertial>
      <visual name="visual_Lower_Leg_B">
        <origin xyz="0 0 0" rpy="0 0 0"/>
        <geometry>
          <mesh filename="LowerLegB.stl" scale="1.0 1.0 1.0"/>
        </geometry>
        <material name="Material"/>
      </visual>
      <collision name="collision_Lower_Leg_B">
        <origin xyz="0 0 0" rpy="0 0 0"/>
        <geometry>
          <mesh filename="collision_LowerLegB.stl" scale="1.0 1.0 1.0"/>
        </geometry>
      </collision>
    </link>

    <link name="link_l_leg_c">
      <inertial>
        <origin xyz="-0.05328 -0.00079 -0.05951" rpy="0 0 0"/>
        <mass value="0.02"/>
        <inertia ixx="2e-05" ixy="0" ixz="0" iyy="3e-05" iyz="0" izz="1e-05"/>
      </inertial>
      <visual name="visual_Lower_Leg_C">
        <origin xyz="0 0 0" rpy="0 0 0"/>
        <geometry>
          <mesh filename="LowerLegC.stl" scale="1.0 1.0 1.0"/>
        </geometry>
        <material name="Material"/>
      </visual>
      <collision name="collision_Lower_Leg_C">
        <origin xyz="0.00075 -0.00079 -0.00069" rpy="0 0 0"/>
        <geometry>
          <mesh filename="collision_LowerLegC.stl" scale="1.0 1.0 1.0"/>
        </geometry>
      </collision>
    </link>

    <link name="link_l_leg_d">
      <inertial>
        <origin xyz="0.00156 0 -0.00066" rpy="0 0 0"/>
        <mass value="0.02"/>
        <inertia ixx="3e-05" ixy="0" ixz="0" iyy="3e-05" iyz="0" izz="1e-05"/>
      </inertial>
      <visual name="visual_Lower_Leg_D">
        <origin xyz="0.00156 0 -0.00066" rpy="0 2.8113 0"/>
        <geometry>
          <mesh filename="LowerLegD.stl" scale="1.0 1.0 1.0"/>
        </geometry>
        <material name="Material"/>
      </visual>
      <collision name="collision_Lower_Leg_D">
        <origin xyz="0.00156 0 -0.00066" rpy="0 2.8113 0"/>
        <geometry>
          <mesh filename="collision_LowerLegD.stl" scale="1.0 1.0 1.0"/>
        </geometry>
      </collision>
    </link>

    <link name="link_root">
      <inertial>
        <origin xyz="0 0 0" rpy="0 0 0"/>
        <mass value="1.2"/>
        <inertia ixx="0.00125" ixy="0" ixz="0" iyy="0.01546" iyz="0" izz="0.01621"/>
      </inertial>
      <visual name="visual_Body_Structure">
        <origin xyz="0 0 0" rpy="0 0 0"/>
        <geometry>
          <mesh filename="Body_Structure.stl" scale="1.0 1.0 1.0"/>
        </geometry>
        <material name="Material"/>
      </visual>
      <visual name="visual_Hip_Aa_Module_A">
        <origin xyz="0 0 0" rpy="0 0 0"/>
        <geometry>
          <mesh filename="HipAaModuleA.stl" scale="1.0 1.0 1.0"/>
        </geometry>
        <material name="Material"/>
      </visual>
      <visual name="visual_Hip_Aa_Module_B">
        <origin xyz="0 0 0" rpy="0 0 0"/>
        <geometry>
          <mesh filename="HipAaModuleB.stl" scale="1.0 1.0 1.0"/>
        </geometry>
        <material name="Material"/>
      </visual>
      <visual name="visual_Hip_Aa_Module_C">
        <origin xyz="0 0 0" rpy="0 0 0"/>
        <geometry>
          <mesh filename="HipAaModuleC.stl" scale="1.0 1.0 1.0"/>
        </geometry>
        <material name="Material"/>
      </visual>
      <visual name="visual_Hip_Aa_Module_D">
        <origin xyz="0 0 0" rpy="0 0 0"/>
        <geometry>
          <mesh filename="HipAaModuleD.stl" scale="1.0 1.0 1.0"/>
        </geometry>
        <material name="Material"/>
      </visual>
      <collision name="collision_root_3">
        <origin xyz="0 0 0" rpy="0 0 0"/>
        <geometry>
          <mesh filename="collision_root.stl" scale="1.0 1.0 1.0"/>
        </geometry>
      </collision>
    </link>

    <link name="link_u_leg_a">
      <inertial>
        <origin xyz="0 0 0" rpy="0 0 0"/>
        <mass value="0.15"/>
        <inertia ixx="0.00015" ixy="0" ixz="0.00011" iyy="0.00025" iyz="0" izz="0.00011"/>
      </inertial>
      <visual name="visual_Upper_Leg_Module_A">
        <origin xyz="0 0 0" rpy="0 0 0"/>
        <geometry>
          <mesh filename="UpperLegModuleA.stl" scale="1.0 1.0 1.0"/>
        </geometry>
        <material name="Material"/>
      </visual>
      <collision name="collision_Upper_Leg_A">
        <origin xyz="0 0 0" rpy="0 0 0"/>
        <geometry>
          <mesh filename="collision_UpperLegA.stl" scale="0.9 0.9 0.9"/>
        </geometry>
      </collision>
    </link>

    <link name="link_u_leg_b">
      <inertial>
        <origin xyz="0 0 0" rpy="0 0 0"/>
        <mass value="0.15"/>
        <inertia ixx="0.00015" ixy="0" ixz="0.00011" iyy="0.00025" iyz="0" izz="0.00011"/>
      </inertial>
      <visual name="visual_Upper_Leg_Module_B">
        <origin xyz="0 0 0" rpy="0 0 0"/>
        <geometry>
          <mesh filename="UpperLegModuleB.stl" scale="1.0 1.0 1.0"/>
        </geometry>
        <material name="Material"/>
      </visual>
      <collision name="Upper Leg Module">
        <origin xyz="0 0 0" rpy="0 0 0"/>
        <geometry>
          <mesh filename="collision_UpperLegB.stl" scale="1.0 1.0 1.0"/>
        </geometry>
      </collision>
    </link>

    <link name="link_u_leg_c">
      <inertial>
        <origin xyz="0 0 0" rpy="0 0 0"/>
        <mass value="0.15"/>
        <inertia ixx="0.00023" ixy="0" ixz="-5e-05" iyy="0.00025" iyz="0" izz="3e-05"/>
      </inertial>
      <visual name="visual_Upper_Leg_Module_C">
        <origin xyz="0 0 0" rpy="0 -1.34948 0"/>
        <geometry>
          <mesh filename="UpperLegModuleC.stl" scale="1.0 1.0 1.0"/>
        </geometry>
        <material name="Material"/>
      </visual>
      <collision name="collision_Upper_Leg_C">
        <origin xyz="0 0 -0.0001" rpy="0 -1.34948 0"/>
        <geometry>
          <mesh filename="collision_UpperLegC.stl" scale="1.0 1.0 1.0"/>
        </geometry>
      </collision>
    </link>

    <link name="link_u_leg_d">
      <inertial>
        <origin xyz="0.0571 0.03543 -0.07324" rpy="0 0 0"/>
        <mass value="0.15"/>
        <inertia ixx="0.00023" ixy="0" ixz="-5e-05" iyy="0.00025" iyz="0" izz="3e-05"/>
      </inertial>
      <visual name="visual_Upper_Leg_Module_D">
        <origin xyz="0.00079 0.02459 0.00036" rpy="0 -1.34948 0"/>
        <geometry>
          <mesh filename="UpperLegModuleD.stl" scale="1.0 1.0 1.0"/>
        </geometry>
        <material name="Material"/>
      </visual>
      <collision name="Upper Leg Module">
        <origin xyz="-0.0002 0.03302 -0.00122" rpy="0 -1.34948 0"/>
        <geometry>
          <mesh filename="collision_UpperLegD.stl" scale="1.0 1.0 1.0"/>
        </geometry>
      </collision>
    </link>

    <joint name="link_hip_a" type="revolute">
      <origin xyz="-0.1939 -0.09 0" rpy="0 0 0"/>
      <parent link="link_root"/>
      <child link="link_hip_a"/>
      <axis xyz="-1.0 0 0"/>
      <dynamics damping="1" friction="1"/>
      <limit lower="-1.31" upper="2.443" effort="55" velocity="28.6"/>
    </joint>

    <joint name="link_hip_b" type="revolute">
      <origin xyz="-0.1939 0.09 0" rpy="0 0 0"/>
      <parent link="link_root"/>
      <child link="link_hip_b"/>
      <axis xyz="-1.0 0 0"/>
      <dynamics damping="1" friction="1"/>
      <limit lower="-1.31" upper="2.443" effort="55" velocity="28.6"/>
    </joint>

    <joint name="link_hip_c" type="revolute">
      <origin xyz="0.1939 -0.09 0" rpy="0 0 0"/>
      <parent link="link_root"/>
      <child link="link_hip_c"/>
      <axis xyz="1.0 0 0"/>
      <dynamics damping="1" friction="1"/>
      <limit lower="-1.31" upper="2.443" effort="55" velocity="28.6"/>
    </joint>

    <joint name="link_hip_d" type="revolute">
      <origin xyz="0.1939 0.09 0" rpy="0 0 0"/>
      <parent link="link_root"/>
      <child link="link_hip_d"/>
      <axis xyz="1.0 0 0"/>
      <dynamics damping="1" friction="1"/>
      <limit lower="-1.31" upper="2.443" effort="55" velocity="28.6"/>
    </joint>

    <joint name="link_l_leg_a" type="revolute">
      <origin xyz="0.10112 -0.05695 -0.12354" rpy="0 0 0"/>
      <parent link="link_u_leg_a"/>
      <child link="link_l_leg_a"/>
      <axis xyz="0 -1.0 0"/>
      <dynamics damping="1" friction="1"/>
      <limit lower="-6.3" upper="6.3" effort="55" velocity="28.6"/>
    </joint>

    <joint name="link_l_leg_b" type="revolute">
      <origin xyz="0.10112 0.05695 -0.12354" rpy="0 0 0"/>
      <parent link="link_u_leg_b"/>
      <child link="link_l_leg_b"/>
      <axis xyz="0 1.0 0"/>
      <dynamics damping="1" friction="1"/>
      <limit lower="-6.3" upper="6.3" effort="55" velocity="28.6"/>
    </joint>

    <joint name="link_l_leg_c" type="revolute">
      <origin xyz="0.09841 -0.05695 -0.12588" rpy="0 0 0"/>
      <parent link="link_u_leg_c"/>
      <child link="link_l_leg_c"/>
      <axis xyz="0 -1.0 0"/>
      <dynamics damping="1" friction="1"/>
      <limit lower="-6.3" upper="6.3" effort="55" velocity="28.6"/>
    </joint>

    <joint name="link_l_leg_d" type="revolute">
      <origin xyz="0.09841 0.05695 -0.12588" rpy="0 -1.34948 0"/>
      <parent link="link_u_leg_d"/>
      <child link="link_l_leg_d"/>
      <axis xyz="0 1.0 0"/>
      <dynamics damping="1" friction="1"/>
      <limit lower="-6.3" upper="6.3" effort="55" velocity="28.6"/>
    </joint>

    <joint name="link_u_leg_a" type="revolute">
      <origin xyz="0 0 0" rpy="0 0 0"/>
      <parent link="link_hip_a"/>
      <child link="link_u_leg_a"/>
      <axis xyz="0 -1.0 0"/>
      <dynamics damping="1" friction="1"/>
      <limit lower="-6.3" upper="6.3" effort="55" velocity="28.6"/>
    </joint>

    <joint name="link_u_leg_b" type="revolute">
      <origin xyz="0 0 0" rpy="0 0 0"/>
      <parent link="link_hip_b"/>
      <child link="link_u_leg_b"/>
      <axis xyz="0 1.0 0"/>
      <dynamics damping="1" friction="1"/>
      <limit lower="-6.3" upper="6.3" effort="55" velocity="28.6"/>
    </joint>

    <joint name="link_u_leg_c" type="revolute">
      <origin xyz="0 0 0" rpy="0 0 0"/>
      <parent link="link_hip_c"/>
      <child link="link_u_leg_c"/>
      <axis xyz="0 -1.0 0"/>
      <dynamics damping="1" friction="1"/>
      <limit lower="-6.3" upper="6.3" effort="55" velocity="28.6"/>
    </joint>

    <joint name="link_u_leg_d" type="revolute">
      <origin xyz="0 0 0" rpy="0 0 0"/>
      <parent link="link_hip_d"/>
      <child link="link_u_leg_d"/>
      <axis xyz="0 1.0 0"/>
      <dynamics damping="1" friction="1"/>
      <limit lower="-6.3" upper="6.3" effort="55" velocity="28.6"/>
    </joint>

  <joint name="imu_joint" type="fixed">
    <parent link="link_root"/>
    <child link="imu_link"/>
    <origin rpy="0 0 0" xyz="0 0 0"/>
  </joint>
  <link name="imu_link">
    <inertial>
      <mass value="0.001"/>
      <origin rpy="0 0 0" xyz="0 0 0"/>
      <inertia ixx="0.0001" ixy="0" ixz="0" iyy="0.0001" iyz="0" izz="0.0001"/>
    </inertial>
    <visual>
      <origin rpy="0 0 0" xyz="0 0 0"/>
      <geometry>
        <box size="0.001 0.001 0.001"/>
      </geometry>
      <material name="red"/>
    </visual>
    <collision>
      <origin rpy="0 0 0" xyz="0 0 0"/>
      <geometry>
        <box size=".001 .001 .001"/>
      </geometry>
    </collision>
  </link>

  <transmission name="FR_hip_tran">
    <type>transmission_interface/SimpleTransmission</type>
    <joint name="link_hip_b">
      <hardwareInterface>hardware_interface/EffortJointInterface</hardwareInterface>
    </joint>
    <actuator name="FR_hip_motor">
      <hardwareInterface>hardware_interface/EffortJointInterface</hardwareInterface>
      <mechanicalReduction>1</mechanicalReduction>
    </actuator>
  </transmission>
  <transmission name="FR_upper_tran">
    <type>transmission_interface/SimpleTransmission</type>
    <joint name="link_u_leg_b">
      <hardwareInterface>hardware_interface/EffortJointInterface</hardwareInterface>
    </joint>
    <actuator name="FR_upper_motor">
      <hardwareInterface>hardware_interface/EffortJointInterface</hardwareInterface>
      <mechanicalReduction>1</mechanicalReduction>
    </actuator>
  </transmission>
  <transmission name="FR_lower_tran">
    <type>transmission_interface/SimpleTransmission</type>
    <joint name="link_l_leg_b">
      <hardwareInterface>hardware_interface/EffortJointInterface</hardwareInterface>
    </joint>
    <actuator name="FR_lower_motor">
      <hardwareInterface>hardware_interface/EffortJointInterface</hardwareInterface>
      <mechanicalReduction>1</mechanicalReduction>
    </actuator>
  </transmission>
    <transmission name="FL_hip_tran">
    <type>transmission_interface/SimpleTransmission</type>
    <joint name="link_hip_a">
      <hardwareInterface>hardware_interface/EffortJointInterface</hardwareInterface>
    </joint>
    <actuator name="FL_hip_motor">
      <hardwareInterface>hardware_interface/EffortJointInterface</hardwareInterface>
      <mechanicalReduction>1</mechanicalReduction>
    </actuator>
  </transmission>
  <transmission name="FL_upper_tran">
    <type>transmission_interface/SimpleTransmission</type>
    <joint name="link_u_leg_a">
      <hardwareInterface>hardware_interface/EffortJointInterface</hardwareInterface>
    </joint>
    <actuator name="FL_upper_motor">
      <hardwareInterface>hardware_interface/EffortJointInterface</hardwareInterface>
      <mechanicalReduction>1</mechanicalReduction>
    </actuator>
  </transmission>
  <transmission name="FL_lower_tran">
    <type>transmission_interface/SimpleTransmission</type>
    <joint name="link_l_leg_a">
      <hardwareInterface>hardware_interface/EffortJointInterface</hardwareInterface>
    </joint>
    <actuator name="FL_lower_motor">
      <hardwareInterface>hardware_interface/EffortJointInterface</hardwareInterface>
      <mechanicalReduction>1</mechanicalReduction>
    </actuator>
  </transmission>
    <transmission name="RR_hip_tran">
    <type>transmission_interface/SimpleTransmission</type>
    <joint name="link_hip_d">
      <hardwareInterface>hardware_interface/EffortJointInterface</hardwareInterface>
    </joint>
    <actuator name="RR_hip_motor">
      <hardwareInterface>hardware_interface/EffortJointInterface</hardwareInterface>
      <mechanicalReduction>1</mechanicalReduction>
    </actuator>
  </transmission>
  <transmission name="RR_upper_tran">
    <type>transmission_interface/SimpleTransmission</type>
    <joint name="link_u_leg_d">
      <hardwareInterface>hardware_interface/EffortJointInterface</hardwareInterface>
    </joint>
    <actuator name="RR_upper_motor">
      <hardwareInterface>hardware_interface/EffortJointInterface</hardwareInterface>
      <mechanicalReduction>1</mechanicalReduction>
    </actuator>
  </transmission>
  <transmission name="RR_lower_tran">
    <type>transmission_interface/SimpleTransmission</type>
    <joint name="link_l_leg_d">
      <hardwareInterface>hardware_interface/EffortJointInterface</hardwareInterface>
    </joint>
    <actuator name="RR_lower_motor">
      <hardwareInterface>hardware_interface/EffortJointInterface</hardwareInterface>
      <mechanicalReduction>1</mechanicalReduction>
    </actuator>
  </transmission>
    <transmission name="RL_hip_tran">
    <type>transmission_interface/SimpleTransmission</type>
    <joint name="link_hip_c">
      <hardwareInterface>hardware_interface/EffortJointInterface</hardwareInterface>
    </joint>
    <actuator name="RL_hip_motor">
      <hardwareInterface>hardware_interface/EffortJointInterface</hardwareInterface>
      <mechanicalReduction>1</mechanicalReduction>
    </actuator>
  </transmission>
  <transmission name="RL_upper_tran">
    <type>transmission_interface/SimpleTransmission</type>
    <joint name="link_u_leg_c">
      <hardwareInterface>hardware_interface/EffortJointInterface</hardwareInterface>
    </joint>
    <actuator name="RL_upper_motor">
      <hardwareInterface>hardware_interface/EffortJointInterface</hardwareInterface>
      <mechanicalReduction>1</mechanicalReduction>
    </actuator>
  </transmission>
  <transmission name="RL_lower_tran">
    <type>transmission_interface/SimpleTransmission</type>
    <joint name="link_l_leg_c">
      <hardwareInterface>hardware_interface/EffortJointInterface</hardwareInterface>
    </joint>
    <actuator name="RL_lower_motor">
      <hardwareInterface>hardware_interface/EffortJointInterface</hardwareInterface>
      <mechanicalReduction>1</mechanicalReduction>
    </actuator>
  </transmission>

    <material name="Material">
      <color rgba="0.64 0.57001 0.34995 1.0"/>
    </material>

  </robot>
