<?xml version="1.0"?>
<!-- created with Phobos 1.0.1 "Capricious Choutengan" -->
  <robot name="robot">

    <link name="link_Head">
      <inertial>
        <origin xyz="0 0 0" rpy="0 0 0"/>
        <mass value="3.5"/>
        <inertia ixx="100000.00475" ixy="0" ixz="0" iyy="100000.00475" iyz="0" izz="100000.00475"/>
      </inertial>
      <visual name="visual_Head">
        <origin xyz="0 0 0" rpy="-1.5708 0 0"/>
        <geometry>
          <mesh filename="Head.stl" scale="1.0 1.0 1.0"/>
        </geometry>
        <material name="asdf1:Beta_HighLimbsGeoSG2"/>
      </visual>
      <collision name="collision_Head">
        <origin xyz="0 0 0" rpy="-1.5708 0 0"/>
        <geometry>
          <mesh filename="c_Head.stl" scale="1.0 1.0 1.0"/>
        </geometry>
      </collision>
    </link>

    <link name="link_Hips">
      <inertial>
        <origin xyz="0 0 0" rpy="0 0 0"/>
        <mass value="5.5"/>
        <inertia ixx="0.001" ixy="0" ixz="0" iyy="0.001" iyz="0" izz="0.001"/>
      </inertial>
      <visual name="visual_Hips">
        <origin xyz="7e-05 -0.00012 0.00035" rpy="0 0 0"/>
        <geometry>
          <mesh filename="Hips.stl" scale="1.0 1.0 1.0"/>
        </geometry>
        <material name="asdf1:Beta_HighLimbsGeoSG2"/>
      </visual>
      <collision name="collision_Hips">
        <origin xyz="0 0 0" rpy="0 0 0"/>
        <geometry>
          <mesh filename="c_Hips.stl" scale="1.0 1.0 1.0"/>
        </geometry>
      </collision>
    </link>

    <link name="link_LeftArm">
      <inertial>
        <origin xyz="0 0 0" rpy="0 0 0"/>
        <mass value="1.3"/>
        <inertia ixx="0.001" ixy="0" ixz="0" iyy="0.001" iyz="0" izz="0.001"/>
      </inertial>
      <visual name="visual_LeftArm">
        <origin xyz="0 0 0" rpy="0 0 0"/>
        <geometry>
          <mesh filename="LeftArm.stl" scale="1.0 1.0 1.0"/>
        </geometry>
        <material name="asdf1:Beta_HighLimbsGeoSG2"/>
      </visual>
      <collision name="collision_LeftArm">
        <origin xyz="0 0 0" rpy="0 0 0"/>
        <geometry>
          <mesh filename="c_LeftArm.stl" scale="1.0 1.0 1.0"/>
        </geometry>
      </collision>
    </link>

    <link name="link_LeftFoot">
      <inertial>
        <origin xyz="0 0 0" rpy="0 0 0"/>
        <mass value="0.7"/>
        <inertia ixx="0.001" ixy="0" ixz="0" iyy="0.001" iyz="0" izz="0.001"/>
      </inertial>
      <visual name="visual_LeftFoot">
        <origin xyz="0 0 0" rpy="0 0 0"/>
        <geometry>
          <mesh filename="LeftFoot.stl" scale="1.0 1.0 1.0"/>
        </geometry>
        <material name="asdf1:Beta_HighLimbsGeoSG2"/>
      </visual>
      <collision name="collision_LeftFoot">
        <origin xyz="0 0 0" rpy="0 0 0"/>
        <geometry>
          <mesh filename="c_LeftFoot.stl" scale="1.0 1.0 1.0"/>
        </geometry>
      </collision>
    </link>

    <link name="link_LeftForeArm">
      <inertial>
        <origin xyz="0 0 0" rpy="0 0 0"/>
        <mass value="0.8"/>
        <inertia ixx="0.001" ixy="0" ixz="0" iyy="0.001" iyz="0" izz="0.001"/>
      </inertial>
      <visual name="visual_LeftForeArm">
        <origin xyz="0 0 0" rpy="0 0 0"/>
        <geometry>
          <mesh filename="LeftForeArm.stl" scale="1.0 1.0 1.0"/>
        </geometry>
        <material name="asdf1:Beta_HighLimbsGeoSG2"/>
      </visual>
      <collision name="collision_LeftForeArm">
        <origin xyz="6e-05 0.00241 -0.00096" rpy="0 0 0"/>
        <geometry>
          <sphere radius="0.04142"/>
        </geometry>
      </collision>
      <collision name="collision_LeftForeArm.1">
        <origin xyz="0 0 0" rpy="0 0 0"/>
        <geometry>
          <mesh filename="c_LeftForeArm.stl" scale="1.0 1.0 1.0"/>
        </geometry>
      </collision>
    </link>

    <link name="link_LeftHand">
      <inertial>
        <origin xyz="0 0 0" rpy="0 0 0"/>
        <mass value="0.6"/>
        <inertia ixx="0.001" ixy="0" ixz="0" iyy="0.001" iyz="0" izz="0.001"/>
      </inertial>
      <visual name="visual_LeftHand">
        <origin xyz="0 0 0" rpy="0 0 0"/>
        <geometry>
          <mesh filename="LeftHand.stl" scale="1.0 1.0 1.0"/>
        </geometry>
        <material name="asdf1:Beta_HighLimbsGeoSG2"/>
      </visual>
      <collision name="collision_LeftHand">
        <origin xyz="-0.0002 2e-05 0.00021" rpy="0 0 0"/>
        <geometry>
          <sphere radius="0.02982"/>
        </geometry>
      </collision>
      <collision name="collision_LeftHand.1">
        <origin xyz="0 0 0" rpy="0 0 0"/>
        <geometry>
          <mesh filename="c_LeftHand.stl" scale="1.0 1.0 1.0"/>
        </geometry>
      </collision>
    </link>

    <link name="link_LeftHandIndex1">
      <inertial>
        <origin xyz="0 0 0" rpy="0 0 0"/>
        <mass value="0.001"/>
        <inertia ixx="0.001" ixy="0" ixz="0" iyy="0.001" iyz="0" izz="0.001"/>
      </inertial>
      <visual name="visual_LeftHandIndex1">
        <origin xyz="0 0 0" rpy="0 0 0"/>
        <geometry>
          <mesh filename="LeftHandIndex1.stl" scale="1.0 1.0 1.0"/>
        </geometry>
        <material name="asdf1:Beta_HighLimbsGeoSG2"/>
      </visual>
      <collision name="collision_LeftHandIndex1">
        <origin xyz="-0.00026 -0.00047 0.00221" rpy="0 0 0"/>
        <geometry>
          <sphere radius="0.01204"/>
        </geometry>
      </collision>
      <collision name="collision_LeftHandIndex1.1">
        <origin xyz="0 0 0" rpy="0 0 0"/>
        <geometry>
          <mesh filename="c_LeftHandIndex.stl" scale="1.0 1.0 1.0"/>
        </geometry>
      </collision>
    </link>

    <link name="link_LeftHandIndex2">
      <inertial>
        <origin xyz="0 0 0" rpy="0 0 0"/>
        <mass value="0.001"/>
        <inertia ixx="0.001" ixy="0" ixz="0" iyy="0.001" iyz="0" izz="0.001"/>
      </inertial>
      <visual name="visual_LeftHandIndex2">
        <origin xyz="0 0 0" rpy="0 0 0"/>
        <geometry>
          <mesh filename="LeftHandIndex2.stl" scale="1.0 1.0 1.0"/>
        </geometry>
        <material name="asdf1:Beta_HighLimbsGeoSG2"/>
      </visual>
      <collision name="collision_LeftHandIndex2">
        <origin xyz="0.00066 0.00024 -0.00012" rpy="0 0 0"/>
        <geometry>
          <sphere radius="0.00977"/>
        </geometry>
      </collision>
      <collision name="collision_LeftHandIndex2.1">
        <origin xyz="0 0 0" rpy="0 0 0"/>
        <geometry>
          <mesh filename="c_LeftHandIndex2.stl" scale="1.0 1.0 1.0"/>
        </geometry>
      </collision>
    </link>

    <link name="link_LeftHandIndex3">
      <inertial>
        <origin xyz="0 0 0" rpy="0 0 0"/>
        <mass value="0.001"/>
        <inertia ixx="0.001" ixy="0" ixz="0" iyy="0.001" iyz="0" izz="0.001"/>
      </inertial>
      <visual name="visual_LeftHandIndex3">
        <origin xyz="0 0 0" rpy="0 0 0"/>
        <geometry>
          <mesh filename="LeftHandIndex3.stl" scale="1.0 1.0 1.0"/>
        </geometry>
        <material name="asdf1:Beta_HighLimbsGeoSG2"/>
      </visual>
      <collision name="collision_LeftHandIndex3">
        <origin xyz="-0.00014 -4e-05 0.00018" rpy="0 0 0"/>
        <geometry>
          <sphere radius="0.00859"/>
        </geometry>
      </collision>
      <collision name="collision_LeftHandIndex3.1">
        <origin xyz="0 0 0" rpy="0 0 0"/>
        <geometry>
          <mesh filename="c_LeftHandIndex3.stl" scale="1.0 1.0 1.0"/>
        </geometry>
      </collision>
    </link>

    <link name="link_LeftHandMiddle1">
      <inertial>
        <origin xyz="0 0 0" rpy="0 0 0"/>
        <mass value="0.001"/>
        <inertia ixx="0.001" ixy="0" ixz="0" iyy="0.001" iyz="0" izz="0.001"/>
      </inertial>
      <visual name="visual_LeftHandMiddle1">
        <origin xyz="0 0 0" rpy="0 0 0"/>
        <geometry>
          <mesh filename="LeftHandMiddle1.stl" scale="1.0 1.0 1.0"/>
        </geometry>
        <material name="asdf1:Beta_HighLimbsGeoSG2"/>
      </visual>
      <collision name="collision_LeftHandMiddle1">
        <origin xyz="-0.00065 -0.00059 0.00265" rpy="0 0 0"/>
        <geometry>
          <sphere radius="0.01297"/>
        </geometry>
      </collision>
      <collision name="collision_LeftHandMiddle1.1">
        <origin xyz="0 0 0" rpy="0 0 0"/>
        <geometry>
          <mesh filename="c_LeftHandMiddle1.stl" scale="1.0 1.0 1.0"/>
        </geometry>
      </collision>
    </link>

    <link name="link_LeftHandMiddle2">
      <inertial>
        <origin xyz="0 0 0" rpy="0 0 0"/>
        <mass value="0.001"/>
        <inertia ixx="0.001" ixy="0" ixz="0" iyy="0.001" iyz="0" izz="0.001"/>
      </inertial>
      <visual name="visual_LeftHandMiddle2">
        <origin xyz="0 0 0" rpy="0 0 0"/>
        <geometry>
          <mesh filename="LeftHandMiddle2.stl" scale="1.0 1.0 1.0"/>
        </geometry>
        <material name="asdf1:Beta_HighLimbsGeoSG2"/>
      </visual>
      <collision name="collision_LeftHandMiddle2">
        <origin xyz="-3e-05 0.00031 0.00025" rpy="0 0 0"/>
        <geometry>
          <sphere radius="0.00975"/>
        </geometry>
      </collision>
      <collision name="collision_LeftHandMiddle2.1">
        <origin xyz="0 0 0" rpy="0 0 0"/>
        <geometry>
          <mesh filename="c_LeftHandMiddle2.stl" scale="1.0 1.0 1.0"/>
        </geometry>
      </collision>
    </link>

    <link name="link_LeftHandMiddle3">
      <inertial>
        <origin xyz="0 0 0" rpy="0 0 0"/>
        <mass value="0.001"/>
        <inertia ixx="0.001" ixy="0" ixz="0" iyy="0.001" iyz="0" izz="0.001"/>
      </inertial>
      <visual name="visual_LeftHandMiddle3">
        <origin xyz="0 0 0" rpy="0 0 0"/>
        <geometry>
          <mesh filename="LeftHandMiddle3.stl" scale="1.0 1.0 1.0"/>
        </geometry>
        <material name="asdf1:Beta_HighLimbsGeoSG2"/>
      </visual>
      <collision name="collision_LeftHandMiddle3">
        <origin xyz="-0.00045 0.00031 0.00029" rpy="0 0 0"/>
        <geometry>
          <sphere radius="0.00831"/>
        </geometry>
      </collision>
      <collision name="collision_LeftHandMiddle3.1">
        <origin xyz="0 0 0" rpy="0 0 0"/>
        <geometry>
          <mesh filename="c_LeftHandMiddle3.stl" scale="1.0 1.0 1.0"/>
        </geometry>
      </collision>
    </link>

    <link name="link_LeftHandPinky1">
      <inertial>
        <origin xyz="0 0 0" rpy="0 0 0"/>
        <mass value="0.001"/>
        <inertia ixx="0.001" ixy="0" ixz="0" iyy="0.001" iyz="0" izz="0.001"/>
      </inertial>
      <visual name="visual_LeftHandPinky1">
        <origin xyz="0 0 0" rpy="0 0 0"/>
        <geometry>
          <mesh filename="LeftHandPinky1.stl" scale="1.0 1.0 1.0"/>
        </geometry>
        <material name="asdf1:Beta_HighLimbsGeoSG2"/>
      </visual>
      <collision name="collision_LeftHandPinky1">
        <origin xyz="-0.0007 -0.0005 0.00293" rpy="0 0 0"/>
        <geometry>
          <sphere radius="0.01219"/>
        </geometry>
      </collision>
      <collision name="collision_LeftHandPinky1.1">
        <origin xyz="0 0 0" rpy="0 0 0"/>
        <geometry>
          <mesh filename="c_LeftHandPinky1.stl" scale="1.0 1.0 1.0"/>
        </geometry>
      </collision>
    </link>

    <link name="link_LeftHandPinky2">
      <inertial>
        <origin xyz="0 0 0" rpy="0 0 0"/>
        <mass value="0.001"/>
        <inertia ixx="0.001" ixy="0" ixz="0" iyy="0.001" iyz="0" izz="0.001"/>
      </inertial>
      <visual name="visual_LeftHandPinky2">
        <origin xyz="0 0 0" rpy="0 0 0"/>
        <geometry>
          <mesh filename="LeftHandPinky2.stl" scale="1.0 1.0 1.0"/>
        </geometry>
        <material name="asdf1:Beta_HighLimbsGeoSG2"/>
      </visual>
      <collision name="collision_LeftHandPinky2">
        <origin xyz="-0.00015 -7e-05 0.00012" rpy="0 0 0"/>
        <geometry>
          <sphere radius="0.00827"/>
        </geometry>
      </collision>
      <collision name="collision_LeftHandPinky2.1">
        <origin xyz="0 0 0" rpy="0 0 0"/>
        <geometry>
          <mesh filename="c_LeftHandPinky2.stl" scale="1.0 1.0 1.0"/>
        </geometry>
      </collision>
    </link>

    <link name="link_LeftHandPinky3">
      <inertial>
        <origin xyz="0 0 0" rpy="0 0 0"/>
        <mass value="0.001"/>
        <inertia ixx="0.001" ixy="0" ixz="0" iyy="0.001" iyz="0" izz="0.001"/>
      </inertial>
      <visual name="visual_LeftHandPinky3">
        <origin xyz="0 0 0" rpy="0 0 0"/>
        <geometry>
          <mesh filename="LeftHandPinky3.stl" scale="1.0 1.0 1.0"/>
        </geometry>
        <material name="asdf1:Beta_HighLimbsGeoSG2"/>
      </visual>
      <collision name="collision_LeftHandPinky3">
        <origin xyz="7e-05 -7e-05 0.00055" rpy="0 0 0"/>
        <geometry>
          <sphere radius="0.0071"/>
        </geometry>
      </collision>
      <collision name="collision_LeftHandPinky3.1">
        <origin xyz="0 0 0" rpy="0 0 0"/>
        <geometry>
          <mesh filename="c_LeftHandPinky3.stl" scale="1.0 1.0 1.0"/>
        </geometry>
      </collision>
    </link>

    <link name="link_LeftHandRing1">
      <inertial>
        <origin xyz="0 0 0" rpy="0 0 0"/>
        <mass value="0.001"/>
        <inertia ixx="0.001" ixy="0" ixz="0" iyy="0.001" iyz="0" izz="0.001"/>
      </inertial>
      <visual name="visual_LeftHandRing1">
        <origin xyz="0 0 0" rpy="0 0 0"/>
        <geometry>
          <mesh filename="LeftHandRing1.stl" scale="1.0 1.0 1.0"/>
        </geometry>
        <material name="Beta_Joints_MAT"/>
      </visual>
      <visual name="visual_LeftHandRing1.1">
        <origin xyz="0 0 0" rpy="0 0 0"/>
        <geometry>
          <mesh filename="LeftHandRing1.1.stl" scale="1.0 1.0 1.0"/>
        </geometry>
        <material name="asdf1:Beta_HighLimbsGeoSG2"/>
      </visual>
      <collision name="collision_LeftHandRing1">
        <origin xyz="-0.00046 -0.00031 0.00236" rpy="0 0 0"/>
        <geometry>
          <sphere radius="0.01255"/>
        </geometry>
      </collision>
      <collision name="collision_LeftHandRing1.1">
        <origin xyz="0 0 0" rpy="0 0 0"/>
        <geometry>
          <mesh filename="c_LeftHandRing1.stl" scale="1.0 1.0 1.0"/>
        </geometry>
      </collision>
    </link>

    <link name="link_LeftHandRing2">
      <inertial>
        <origin xyz="0 0 0" rpy="0 0 0"/>
        <mass value="0.001"/>
        <inertia ixx="0.001" ixy="0" ixz="0" iyy="0.001" iyz="0" izz="0.001"/>
      </inertial>
      <visual name="visual_LeftHandRing2">
        <origin xyz="0 0 0" rpy="0 0 0"/>
        <geometry>
          <mesh filename="LeftHandRing2.stl" scale="1.0 1.0 1.0"/>
        </geometry>
        <material name="asdf1:Beta_HighLimbsGeoSG2"/>
      </visual>
      <collision name="collision_LeftHandRing2">
        <origin xyz="-4e-05 -6e-05 7e-05" rpy="0 0 0"/>
        <geometry>
          <sphere radius="0.00966"/>
        </geometry>
      </collision>
      <collision name="collision_LeftHandRing2.1">
        <origin xyz="0 0 0" rpy="0 0 0"/>
        <geometry>
          <mesh filename="c_LeftHandRing2.stl" scale="1.0 1.0 1.0"/>
        </geometry>
      </collision>
    </link>

    <link name="link_LeftHandRing3">
      <inertial>
        <origin xyz="0 0 0" rpy="0 0 0"/>
        <mass value="0.001"/>
        <inertia ixx="0.001" ixy="0" ixz="0" iyy="0.001" iyz="0" izz="0.001"/>
      </inertial>
      <visual name="visual_LeftHandRing3">
        <origin xyz="0 0 0" rpy="0 0 0"/>
        <geometry>
          <mesh filename="LeftHandRing3.stl" scale="1.0 1.0 1.0"/>
        </geometry>
        <material name="asdf1:Beta_HighLimbsGeoSG2"/>
      </visual>
      <collision name="collision_LeftHandRing3">
        <origin xyz="-6e-05 -0.00026 0.00047" rpy="0 0 0"/>
        <geometry>
          <sphere radius="0.0085"/>
        </geometry>
      </collision>
      <collision name="collision_LeftHandRing3.1">
        <origin xyz="0 0 0" rpy="0 0 0"/>
        <geometry>
          <mesh filename="c_LeftHandRing3.stl" scale="1.0 1.0 1.0"/>
        </geometry>
      </collision>
    </link>

    <link name="link_LeftHandThumb1">
      <inertial>
        <origin xyz="0 0 0" rpy="0 0 0"/>
        <mass value="0.001"/>
        <inertia ixx="0.001" ixy="0" ixz="0" iyy="0.001" iyz="0" izz="0.001"/>
      </inertial>
      <visual name="visual_LeftHandThumb1">
        <origin xyz="0 0 0" rpy="0 0 0"/>
        <geometry>
          <mesh filename="LeftHandThumb1.stl" scale="1.0 1.0 1.0"/>
        </geometry>
        <material name="asdf1:Beta_HighLimbsGeoSG2"/>
      </visual>
      <collision name="collision_LeftHandThumb1">
        <origin xyz="0 0 0" rpy="0 0 0"/>
        <geometry>
          <sphere radius="0.01773"/>
        </geometry>
      </collision>
      <collision name="collision_LeftHandThumb1.1">
        <origin xyz="0 0 0" rpy="0 0 0"/>
        <geometry>
          <mesh filename="c_LeftHandThumb1.stl" scale="1.0 1.0 1.0"/>
        </geometry>
      </collision>
    </link>

    <link name="link_LeftHandThumb2">
      <inertial>
        <origin xyz="0 0 0" rpy="0 0 0"/>
        <mass value="0.001"/>
        <inertia ixx="0.001" ixy="0" ixz="0" iyy="0.001" iyz="0" izz="0.001"/>
      </inertial>
      <visual name="visual_LeftHandThumb2">
        <origin xyz="0 0 0" rpy="0 0 0"/>
        <geometry>
          <mesh filename="LeftHandThumb2.stl" scale="1.0 1.0 1.0"/>
        </geometry>
        <material name="asdf1:Beta_HighLimbsGeoSG2"/>
      </visual>
      <collision name="collision_LeftHandThumb2">
        <origin xyz="0 0 0" rpy="1.5708 0 -1e-05"/>
        <geometry>
          <sphere radius="0.01069"/>
        </geometry>
      </collision>
      <collision name="collision_LeftHandThumb2.1">
        <origin xyz="0 0 0" rpy="1.5708 0 -1e-05"/>
        <geometry>
          <mesh filename="c_LeftHandThumb2.stl" scale="0.01 0.01 0.01"/>
        </geometry>
      </collision>
    </link>

    <link name="link_LeftHandThumb3">
      <inertial>
        <origin xyz="0 0 0" rpy="0 0 0"/>
        <mass value="0.001"/>
        <inertia ixx="0.001" ixy="0" ixz="0" iyy="0.001" iyz="0" izz="0.001"/>
      </inertial>
      <visual name="visual_LeftHandThumb3">
        <origin xyz="0 0 0" rpy="0 0 0"/>
        <geometry>
          <mesh filename="LeftHandThumb3.stl" scale="1.0 1.0 1.0"/>
        </geometry>
        <material name="asdf1:Beta_HighLimbsGeoSG2"/>
      </visual>
      <collision name="collision_LeftHandThumb3">
        <origin xyz="0 0 0" rpy="0 0 0"/>
        <geometry>
          <sphere radius="0.00798"/>
        </geometry>
      </collision>
      <collision name="collision_LeftHandThumb3.1">
        <origin xyz="0 0 0" rpy="0 0 0"/>
        <geometry>
          <mesh filename="c_LeftHandThumb3.stl" scale="1.0 1.0 1.0"/>
        </geometry>
      </collision>
    </link>

    <link name="link_LeftLeg">
      <inertial>
        <origin xyz="-0.00231 0.00777 -0.1772" rpy="0 0 0"/>
        <mass value="2.0"/>
        <inertia ixx="0.001" ixy="0" ixz="0" iyy="0.001" iyz="0" izz="0.001"/>
      </inertial>
      <visual name="visual_LeftLeg">
        <origin xyz="0 0 0" rpy="0 0 0"/>
        <geometry>
          <mesh filename="LeftLeg.stl" scale="1.0 1.0 1.0"/>
        </geometry>
        <material name="asdf1:Beta_HighLimbsGeoSG2"/>
      </visual>
      <collision name="collision_LeftLeg">
        <origin xyz="-0.00023 0.00066 0.00176" rpy="0 0 0"/>
        <geometry>
          <sphere radius="0.06134"/>
        </geometry>
      </collision>
      <collision name="collision_LeftLeg.1">
        <origin xyz="0 0 0" rpy="0 0 0"/>
        <geometry>
          <mesh filename="c_LeftLeg.stl" scale="1.0 1.0 1.0"/>
        </geometry>
      </collision>
    </link>

    <link name="link_LeftShoulder">
      <inertial>
        <origin xyz="0 0 0" rpy="0 0 0"/>
        <mass value="0.1"/>
        <inertia ixx="0.001" ixy="0" ixz="0" iyy="0.001" iyz="0" izz="0.001"/>
      </inertial>
      <visual name="visual_LeftShoulder">
        <origin xyz="0.10542 0.02294 -0.0055" rpy="0 0 0"/>
        <geometry>
          <mesh filename="LeftShoulder.stl" scale="1.0 1.0 1.0"/>
        </geometry>
        <material name="Beta_Joints_MAT"/>
      </visual>
      <collision name="collision_LeftShoulder">
        <origin xyz="0.10542 0.02293 -0.0055" rpy="0 0 0"/>
        <geometry>
          <sphere radius="0.04861"/>
        </geometry>
      </collision>
    </link>

    <link name="link_LeftToeBase">
      <inertial>
        <origin xyz="0 0 0" rpy="0 0 0"/>
        <mass value="0.2"/>
        <inertia ixx="0.001" ixy="0" ixz="0" iyy="0.001" iyz="0" izz="0.001"/>
      </inertial>
      <visual name="visual_LeftToeBase">
        <origin xyz="0 0 0" rpy="0 0 0"/>
        <geometry>
          <mesh filename="LeftToeBase.stl" scale="1.0 1.0 1.0"/>
        </geometry>
        <material name="asdf1:Beta_HighLimbsGeoSG2"/>
      </visual>
      <collision name="collision_LeftToeBase">
        <origin xyz="0 0 0" rpy="0 0 0"/>
        <geometry>
          <mesh filename="c_LeftToeBase.stl" scale="1.0 1.0 1.0"/>
        </geometry>
      </collision>
    </link>

    <link name="link_LeftUpLeg">
      <inertial>
        <origin xyz="0 -0.00269 -0.44503" rpy="0 0 0"/>
        <mass value="7.0"/>
        <inertia ixx="0.001" ixy="0" ixz="0" iyy="0.001" iyz="0" izz="0.001"/>
      </inertial>
      <visual name="visual_LeftUpLeg">
        <origin xyz="0 -0.00269 -0.44503" rpy="0 0 0"/>
        <geometry>
          <mesh filename="LeftUpLeg.stl" scale="1.0 1.0 1.0"/>
        </geometry>
        <material name="asdf1:Beta_HighLimbsGeoSG2"/>
      </visual>
      <collision name="collision_LeftUpLeg">
        <origin xyz="-0.03987 0.00081 0.00143" rpy="0 0 0"/>
        <geometry>
          <sphere radius="0.1245"/>
        </geometry>
      </collision>
      <collision name="collision_LeftUpLeg.1">
        <origin xyz="0 -0.00269 -0.44503" rpy="0 0 0"/>
        <geometry>
          <mesh filename="c_LeftUpLeg.stl" scale="1.0 1.0 1.0"/>
        </geometry>
      </collision>
    </link>

    <link name="link_Neck">
      <inertial>
        <origin xyz="0 0 0" rpy="0 0 0"/>
        <mass value="0.8"/>
        <inertia ixx="0.001" ixy="0" ixz="0" iyy="0.001" iyz="0" izz="0.001"/>
      </inertial>
      <visual name="visual_Neck">
        <origin xyz="-0.00019 -0.01339 0.04229" rpy="0 0 0"/>
        <geometry>
          <mesh filename="Neck.stl" scale="1.0 1.0 1.0"/>
        </geometry>
        <material name="Beta_Joints_MAT"/>
      </visual>
      <collision name="collision_Neck">
        <origin xyz="-0.00019 -0.01339 0.04229" rpy="0 0 0"/>
        <geometry>
          <sphere radius="0.05128"/>
        </geometry>
      </collision>
    </link>

    <link name="link_RightArm">
      <inertial>
        <origin xyz="0 0 0" rpy="0 0 0"/>
        <mass value="1.3"/>
        <inertia ixx="0.001" ixy="0" ixz="0" iyy="0.001" iyz="0" izz="0.001"/>
      </inertial>
      <visual name="visual_RightArm">
        <origin xyz="0 0 0" rpy="0 0 0"/>
        <geometry>
          <mesh filename="RightArm.stl" scale="1.0 1.0 1.0"/>
        </geometry>
        <material name="asdf1:Beta_HighLimbsGeoSG2"/>
      </visual>
      <collision name="collision_RightArm">
        <origin xyz="0 0 0" rpy="0 0 0"/>
        <geometry>
          <mesh filename="c_RightArm.stl" scale="1.0 1.0 1.0"/>
        </geometry>
      </collision>
    </link>

    <link name="link_RightFoot">
      <inertial>
        <origin xyz="0 0 0" rpy="0 0 0"/>
        <mass value="0.7"/>
        <inertia ixx="0.001" ixy="0" ixz="0" iyy="0.001" iyz="0" izz="0.001"/>
      </inertial>
      <visual name="visual_RightFoot">
        <origin xyz="0 0 0" rpy="0 0 0"/>
        <geometry>
          <mesh filename="RightFoot.stl" scale="1.0 1.0 1.0"/>
        </geometry>
        <material name="asdf1:Beta_HighLimbsGeoSG2"/>
      </visual>
      <collision name="collision_RightFoot">
        <origin xyz="0 0 0" rpy="0 0 0"/>
        <geometry>
          <mesh filename="c_RightFoot.stl" scale="1.0 1.0 1.0"/>
        </geometry>
      </collision>
    </link>

    <link name="link_RightForeArm">
      <inertial>
        <origin xyz="0 0 0" rpy="0 0 0"/>
        <mass value="0.8"/>
        <inertia ixx="0.001" ixy="0" ixz="0" iyy="0.001" iyz="0" izz="0.001"/>
      </inertial>
      <visual name="visual_RightForeArm">
        <origin xyz="0 0 0" rpy="0 0 0"/>
        <geometry>
          <mesh filename="RightForeArm.stl" scale="1.0 1.0 1.0"/>
        </geometry>
        <material name="asdf1:Beta_HighLimbsGeoSG2"/>
      </visual>
      <collision name="collision_RightForeArm">
        <origin xyz="-0.00355 -0.0036 0.00044" rpy="0 0 0"/>
        <geometry>
          <sphere radius="0.03853"/>
        </geometry>
      </collision>
      <collision name="collision_RightForeArm.1">
        <origin xyz="0 0 0" rpy="0 0 0"/>
        <geometry>
          <mesh filename="c_RightForeArm.stl" scale="1.0 1.0 1.0"/>
        </geometry>
      </collision>
    </link>

    <link name="link_RightHand">
      <inertial>
        <origin xyz="0 0 0" rpy="0 0 0"/>
        <mass value="0.6"/>
        <inertia ixx="0.001" ixy="0" ixz="0" iyy="0.001" iyz="0" izz="0.001"/>
      </inertial>
      <visual name="visual_RightHand">
        <origin xyz="0 0 0" rpy="0 0 0"/>
        <geometry>
          <mesh filename="RightHand.stl" scale="1.0 1.0 1.0"/>
        </geometry>
        <material name="asdf1:Beta_HighLimbsGeoSG2"/>
      </visual>
      <collision name="collision_RightHand">
        <origin xyz="3e-05 -0.0001 0.00035" rpy="0 0 0"/>
        <geometry>
          <sphere radius="0.02982"/>
        </geometry>
      </collision>
      <collision name="collision_RightHand.1">
        <origin xyz="0 0 0" rpy="0 0 0"/>
        <geometry>
          <mesh filename="c_RightHand.stl" scale="1.0 1.0 1.0"/>
        </geometry>
      </collision>
    </link>

    <link name="link_RightHandIndex1">
      <inertial>
        <origin xyz="0 0 0" rpy="0 0 0"/>
        <mass value="0.001"/>
        <inertia ixx="0.001" ixy="0" ixz="0" iyy="0.001" iyz="0" izz="0.001"/>
      </inertial>
      <visual name="visual_RightHandIndex1">
        <origin xyz="0 0 0" rpy="0 0 0"/>
        <geometry>
          <mesh filename="RightHandIndex1.stl" scale="1.0 1.0 1.0"/>
        </geometry>
        <material name="Beta_Joints_MAT"/>
      </visual>
      <collision name="collision_RightHandIndex1">
        <origin xyz="0.00039 -0.00055 0.00302" rpy="0 0 0"/>
        <geometry>
          <sphere radius="0.01204"/>
        </geometry>
      </collision>
      <collision name="collision_RightHandIndex1.1">
        <origin xyz="0 0 0" rpy="0 0 0"/>
        <geometry>
          <mesh filename="c_RightHandIndex1.stl" scale="1.0 1.0 1.0"/>
        </geometry>
      </collision>
    </link>

    <link name="link_RightHandIndex2">
      <inertial>
        <origin xyz="0 0 0" rpy="0 0 0"/>
        <mass value="0.001"/>
        <inertia ixx="0.001" ixy="0" ixz="0" iyy="0.001" iyz="0" izz="0.001"/>
      </inertial>
      <visual name="visual_RightHandIndex2">
        <origin xyz="0 0 0" rpy="0 0 0"/>
        <geometry>
          <mesh filename="RightHandIndex2.stl" scale="1.0 1.0 1.0"/>
        </geometry>
        <material name="asdf1:Beta_HighLimbsGeoSG2"/>
      </visual>
      <collision name="collision_RightHandIndex2">
        <origin xyz="0.00016 -0.00012 0.00015" rpy="0 0 0"/>
        <geometry>
          <sphere radius="0.00977"/>
        </geometry>
      </collision>
      <collision name="collision_RightHandIndex2.1">
        <origin xyz="0 0 0" rpy="0 0 0"/>
        <geometry>
          <mesh filename="c_RightHandIndex2.stl" scale="1.0 1.0 1.0"/>
        </geometry>
      </collision>
    </link>

    <link name="link_RightHandIndex3">
      <inertial>
        <origin xyz="0 0 0" rpy="0 0 0"/>
        <mass value="0.001"/>
        <inertia ixx="0.001" ixy="0" ixz="0" iyy="0.001" iyz="0" izz="0.001"/>
      </inertial>
      <visual name="visual_RightHandIndex3">
        <origin xyz="0 0 0" rpy="0 0 0"/>
        <geometry>
          <mesh filename="RightHandIndex3.stl" scale="1.0 1.0 1.0"/>
        </geometry>
        <material name="asdf1:Beta_HighLimbsGeoSG2"/>
      </visual>
      <collision name="collision_RightHandIndex3">
        <origin xyz="-0.00044 -7e-05 -0.00012" rpy="0 0 0"/>
        <geometry>
          <sphere radius="0.00859"/>
        </geometry>
      </collision>
      <collision name="collision_RightHandIndex3.1">
        <origin xyz="0 0 0" rpy="0 0 0"/>
        <geometry>
          <mesh filename="c_RightHandIndex3.stl" scale="1.0 1.0 1.0"/>
        </geometry>
      </collision>
    </link>

    <link name="link_RightHandMiddle1">
      <inertial>
        <origin xyz="0 0 0" rpy="0 0 0"/>
        <mass value="0.001"/>
        <inertia ixx="0.001" ixy="0" ixz="0" iyy="0.001" iyz="0" izz="0.001"/>
      </inertial>
      <visual name="visual_RightHandMiddle1">
        <origin xyz="0 0 0" rpy="0 0 0"/>
        <geometry>
          <mesh filename="RightHandMiddle1.stl" scale="1.0 1.0 1.0"/>
        </geometry>
        <material name="asdf1:Beta_HighLimbsGeoSG2"/>
      </visual>
      <collision name="collision_RightHandMiddle1">
        <origin xyz="0.00049 -0.00047 0.00253" rpy="0 0 0"/>
        <geometry>
          <sphere radius="0.01297"/>
        </geometry>
      </collision>
      <collision name="collision_RightHandMiddle1.1">
        <origin xyz="0 0 0" rpy="0 0 0"/>
        <geometry>
          <mesh filename="c_RightHandMiddle1.stl" scale="1.0 1.0 1.0"/>
        </geometry>
      </collision>
    </link>

    <link name="link_RightHandMiddle2">
      <inertial>
        <origin xyz="0 0 0" rpy="0 0 0"/>
        <mass value="0.001"/>
        <inertia ixx="0.001" ixy="0" ixz="0" iyy="0.001" iyz="0" izz="0.001"/>
      </inertial>
      <visual name="visual_RightHandMiddle2">
        <origin xyz="0 0 0" rpy="0 0 0"/>
        <geometry>
          <mesh filename="RightHandMiddle2.stl" scale="1.0 1.0 1.0"/>
        </geometry>
        <material name="asdf1:Beta_HighLimbsGeoSG2"/>
      </visual>
      <collision name="collision_RightHandMiddle2">
        <origin xyz="-9e-05 -4e-05 0.0002" rpy="0 0 0"/>
        <geometry>
          <sphere radius="0.00975"/>
        </geometry>
      </collision>
      <collision name="collision_RightHandMiddle2.1">
        <origin xyz="0 0 0" rpy="0 0 0"/>
        <geometry>
          <mesh filename="c_RightHandMiddle2.stl" scale="1.0 1.0 1.0"/>
        </geometry>
      </collision>
    </link>

    <link name="link_RightHandMiddle3">
      <inertial>
        <origin xyz="0 0 0" rpy="0 0 0"/>
        <mass value="0.001"/>
        <inertia ixx="0.001" ixy="0" ixz="0" iyy="0.001" iyz="0" izz="0.001"/>
      </inertial>
      <visual name="visual_RightHandMiddle3">
        <origin xyz="0 0 0" rpy="0 0 0"/>
        <geometry>
          <mesh filename="RightHandMiddle3.stl" scale="1.0 1.0 1.0"/>
        </geometry>
        <material name="Beta_Joints_MAT"/>
      </visual>
      <collision name="collision_RightHandMiddle3">
        <origin xyz="-0.00015 -4e-05 0.00043" rpy="0 0 0"/>
        <geometry>
          <sphere radius="0.00831"/>
        </geometry>
      </collision>
      <collision name="collision_RightHandMiddle3.1">
        <origin xyz="0 0 0" rpy="0 0 0"/>
        <geometry>
          <mesh filename="c_RightHandMiddle3.stl" scale="1.0 1.0 1.0"/>
        </geometry>
      </collision>
    </link>

    <link name="link_RightHandPinky1">
      <inertial>
        <origin xyz="0 0 0" rpy="0 0 0"/>
        <mass value="0.001"/>
        <inertia ixx="0.001" ixy="0" ixz="0" iyy="0.001" iyz="0" izz="0.001"/>
      </inertial>
      <visual name="visual_RightHandPinky1">
        <origin xyz="0 0 0" rpy="0 0 0"/>
        <geometry>
          <mesh filename="RightHandPinky1.stl" scale="1.0 1.0 1.0"/>
        </geometry>
        <material name="asdf1:Beta_HighLimbsGeoSG2"/>
      </visual>
      <collision name="collision_RightHandPinky1">
        <origin xyz="0.00094 -0.0006 0.00247" rpy="0 0 0"/>
        <geometry>
          <sphere radius="0.01219"/>
        </geometry>
      </collision>
      <collision name="collision_RightHandPinky1.1">
        <origin xyz="0 0 0" rpy="0 0 0"/>
        <geometry>
          <mesh filename="c_RightHandPinky1.stl" scale="1.0 1.0 1.0"/>
        </geometry>
      </collision>
    </link>

    <link name="link_RightHandPinky2">
      <inertial>
        <origin xyz="0 0 0" rpy="0 0 0"/>
        <mass value="0.001"/>
        <inertia ixx="0.001" ixy="0" ixz="0" iyy="0.001" iyz="0" izz="0.001"/>
      </inertial>
      <visual name="visual_RightHandPinky2">
        <origin xyz="0 0 0" rpy="0 0 0"/>
        <geometry>
          <mesh filename="RightHandPinky2.stl" scale="1.0 1.0 1.0"/>
        </geometry>
        <material name="Beta_Joints_MAT"/>
      </visual>
      <collision name="collision_RightHandPinky2">
        <origin xyz="1e-05 -0.00018 5e-05" rpy="0 0 0"/>
        <geometry>
          <sphere radius="0.00827"/>
        </geometry>
      </collision>
      <collision name="collision_RightHandPinky2.1">
        <origin xyz="0 0 0" rpy="0 0 0"/>
        <geometry>
          <mesh filename="c_RightHandPinky2.stl" scale="1.0 1.0 1.0"/>
        </geometry>
      </collision>
    </link>

    <link name="link_RightHandPinky3">
      <inertial>
        <origin xyz="0 0 0" rpy="0 0 0"/>
        <mass value="0.001"/>
        <inertia ixx="0.001" ixy="0" ixz="0" iyy="0.001" iyz="0" izz="0.001"/>
      </inertial>
      <visual name="visual_RightHandPinky3">
        <origin xyz="0 0 0" rpy="0 0 0"/>
        <geometry>
          <mesh filename="RightHandPinky3.stl" scale="1.0 1.0 1.0"/>
        </geometry>
        <material name="asdf1:Beta_HighLimbsGeoSG2"/>
      </visual>
      <collision name="collision_RightHandPinky3">
        <origin xyz="-0.00019 -0.00018 0.00031" rpy="0 0 0"/>
        <geometry>
          <sphere radius="0.0071"/>
        </geometry>
      </collision>
      <collision name="collision_RightHandPinky3.1">
        <origin xyz="0 0 0" rpy="0 0 0"/>
        <geometry>
          <mesh filename="c_RightHandPinky3.stl" scale="1.0 1.0 1.0"/>
        </geometry>
      </collision>
    </link>

    <link name="link_RightHandRing1">
      <inertial>
        <origin xyz="0 0 0" rpy="0 0 0"/>
        <mass value="0.001"/>
        <inertia ixx="0.001" ixy="0" ixz="0" iyy="0.001" iyz="0" izz="0.001"/>
      </inertial>
      <visual name="visual_RightHandRing1">
        <origin xyz="0 0 0" rpy="0 0 0"/>
        <geometry>
          <mesh filename="RightHandRing1.stl" scale="1.0 1.0 1.0"/>
        </geometry>
        <material name="asdf1:Beta_HighLimbsGeoSG2"/>
      </visual>
      <collision name="collision_RightHandRing1">
        <origin xyz="0.00046 -0.00013 0.00281" rpy="0 0 0"/>
        <geometry>
          <sphere radius="0.01255"/>
        </geometry>
      </collision>
      <collision name="collision_RightHandRing1.1">
        <origin xyz="0 0 0" rpy="0 0 0"/>
        <geometry>
          <mesh filename="c_RightHandRing1.stl" scale="1.0 1.0 1.0"/>
        </geometry>
      </collision>
    </link>

    <link name="link_RightHandRing2">
      <inertial>
        <origin xyz="0 0 0" rpy="0 0 0"/>
        <mass value="0.001"/>
        <inertia ixx="0.001" ixy="0" ixz="0" iyy="0.001" iyz="0" izz="0.001"/>
      </inertial>
      <visual name="visual_RightHandRing2">
        <origin xyz="0 0 0" rpy="0 0 0"/>
        <geometry>
          <mesh filename="RightHandRing2.stl" scale="1.0 1.0 1.0"/>
        </geometry>
        <material name="asdf1:Beta_HighLimbsGeoSG2"/>
      </visual>
      <collision name="collision_RightHandRing2">
        <origin xyz="-4e-05 -2e-05 0.00017" rpy="0 0 0"/>
        <geometry>
          <sphere radius="0.00966"/>
        </geometry>
      </collision>
      <collision name="collision_RightHandRing2.1">
        <origin xyz="0 0 0" rpy="0 0 0"/>
        <geometry>
          <mesh filename="c_RightHandRing2.stl" scale="1.0 1.0 1.0"/>
        </geometry>
      </collision>
    </link>

    <link name="link_RightHandRing3">
      <inertial>
        <origin xyz="0 0 0" rpy="0 0 0"/>
        <mass value="0.001"/>
        <inertia ixx="0.001" ixy="0" ixz="0" iyy="0.001" iyz="0" izz="0.001"/>
      </inertial>
      <visual name="visual_RightHandRing3">
        <origin xyz="0 0 0" rpy="0 0 0"/>
        <geometry>
          <mesh filename="RightHandRing3.stl" scale="1.0 1.0 1.0"/>
        </geometry>
        <material name="asdf1:Beta_HighLimbsGeoSG2"/>
      </visual>
      <collision name="collision_RightHandRing3">
        <origin xyz="0 -0.00034 0.00017" rpy="0 0 0"/>
        <geometry>
          <sphere radius="0.0085"/>
        </geometry>
      </collision>
      <collision name="collision_RightHandRing3.1">
        <origin xyz="0 0 0" rpy="0 0 0"/>
        <geometry>
          <mesh filename="c_RightHandRing3.stl" scale="1.0 1.0 1.0"/>
        </geometry>
      </collision>
    </link>

    <link name="link_RightHandThumb1">
      <inertial>
        <origin xyz="0 0 0" rpy="0 0 0"/>
        <mass value="0.001"/>
        <inertia ixx="0.001" ixy="0" ixz="0" iyy="0.001" iyz="0" izz="0.001"/>
      </inertial>
      <visual name="visual_RightHandThumb1">
        <origin xyz="0 0 0" rpy="0 0 0"/>
        <geometry>
          <mesh filename="RightHandThumb1.stl" scale="1.0 1.0 1.0"/>
        </geometry>
        <material name="asdf1:Beta_HighLimbsGeoSG2"/>
      </visual>
      <collision name="collision_RightHandThumb1">
        <origin xyz="-0.0001 -0.0001 0.00033" rpy="0 0 0"/>
        <geometry>
          <sphere radius="0.01832"/>
        </geometry>
      </collision>
      <collision name="collision_RightHandThumb1.1">
        <origin xyz="0 0 0" rpy="0 0 0"/>
        <geometry>
          <mesh filename="c_RightHandThumb1.stl" scale="1.0 1.0 1.0"/>
        </geometry>
      </collision>
    </link>

    <link name="link_RightHandThumb2">
      <inertial>
        <origin xyz="0 0 0" rpy="0 0 0"/>
        <mass value="0.001"/>
        <inertia ixx="0.001" ixy="0" ixz="0" iyy="0.001" iyz="0" izz="0.001"/>
      </inertial>
      <visual name="visual_RightHandThumb2">
        <origin xyz="0 0 0" rpy="0 0 0"/>
        <geometry>
          <mesh filename="RightHandThumb2.stl" scale="1.0 1.0 1.0"/>
        </geometry>
        <material name="asdf1:Beta_HighLimbsGeoSG2"/>
      </visual>
      <collision name="collision_RightHandThumb2">
        <origin xyz="0 0 0" rpy="0 0 0"/>
        <geometry>
          <sphere radius="0.01094"/>
        </geometry>
      </collision>
      <collision name="collision_RightHandThumb2.1">
        <origin xyz="0 0 0" rpy="0 0 0"/>
        <geometry>
          <mesh filename="c_RightHandThumb2.stl" scale="1.0 1.0 1.0"/>
        </geometry>
      </collision>
    </link>

    <link name="link_RightHandThumb3">
      <inertial>
        <origin xyz="0 0 0" rpy="0 0 0"/>
        <mass value="0.001"/>
        <inertia ixx="0.001" ixy="0" ixz="0" iyy="0.001" iyz="0" izz="0.001"/>
      </inertial>
      <visual name="visual_RightHandThumb3">
        <origin xyz="0 0 0" rpy="0 0 0"/>
        <geometry>
          <mesh filename="RightHandThumb3.stl" scale="1.0 1.0 1.0"/>
        </geometry>
        <material name="asdf1:Beta_HighLimbsGeoSG2"/>
      </visual>
      <collision name="collision_RightHandThumb3">
        <origin xyz="0 0 0" rpy="0 0 0"/>
        <geometry>
          <sphere radius="0.00816"/>
        </geometry>
      </collision>
      <collision name="collision_RightHandThumb3.1">
        <origin xyz="0 0 0" rpy="0 0 0"/>
        <geometry>
          <mesh filename="c_RightHandThumb3.stl" scale="1.0 1.0 1.0"/>
        </geometry>
      </collision>
    </link>

    <link name="link_RightLeg">
      <inertial>
        <origin xyz="0 0 0" rpy="0 0 0"/>
        <mass value="2.0"/>
        <inertia ixx="0.001" ixy="0" ixz="0" iyy="0.001" iyz="0" izz="0.001"/>
      </inertial>
      <visual name="visual_RightLeg">
        <origin xyz="0 0 0" rpy="0 0 0"/>
        <geometry>
          <mesh filename="RightLeg.stl" scale="1.0 1.0 1.0"/>
        </geometry>
        <material name="asdf1:Beta_HighLimbsGeoSG2"/>
      </visual>
      <collision name="collision_RightLeg">
        <origin xyz="-0.00049 -9e-05 0.00106" rpy="0 0 0"/>
        <geometry>
          <sphere radius="0.06158"/>
        </geometry>
      </collision>
      <collision name="collision_RightLeg.1">
        <origin xyz="0 0 0" rpy="0 0 0"/>
        <geometry>
          <mesh filename="c_RightLeg.stl" scale="1.0 1.0 1.0"/>
        </geometry>
      </collision>
    </link>

    <link name="link_RightShoulder">
      <inertial>
        <origin xyz="0 0 0" rpy="0 0 0"/>
        <mass value="0.1"/>
        <inertia ixx="0.001" ixy="0" ixz="0" iyy="0.001" iyz="0" izz="0.001"/>
      </inertial>
      <visual name="visual_RightShoulder">
        <origin xyz="-0.10623 0.02179 -0.00584" rpy="0 0 0"/>
        <geometry>
          <mesh filename="RightShoulder.stl" scale="1.0 1.0 1.0"/>
        </geometry>
        <material name="Beta_Joints_MAT"/>
      </visual>
      <collision name="collision_RightShoulder">
        <origin xyz="-0.10623 0.02179 -0.00584" rpy="0 0 0"/>
        <geometry>
          <sphere radius="0.04861"/>
        </geometry>
      </collision>
    </link>

    <link name="link_RightToeBase">
      <inertial>
        <origin xyz="0 0 0" rpy="0 0 0"/>
        <mass value="0.2"/>
        <inertia ixx="0.001" ixy="0" ixz="0" iyy="0.001" iyz="0" izz="0.001"/>
      </inertial>
      <visual name="visual_RightToeBase">
        <origin xyz="0 0 0" rpy="0 0 0"/>
        <geometry>
          <mesh filename="RightToeBase.stl" scale="1.0 1.0 1.0"/>
        </geometry>
        <material name="asdf1:Beta_HighLimbsGeoSG2"/>
      </visual>
      <collision name="collision_RightToeBase">
        <origin xyz="0 0 0" rpy="0 0 0"/>
        <geometry>
          <mesh filename="c_RightToeBase.stl" scale="1.0 1.0 1.0"/>
        </geometry>
      </collision>
    </link>

    <link name="link_RightUpLeg">
      <inertial>
        <origin xyz="0 0 0" rpy="0 0 0"/>
        <mass value="7.0"/>
        <inertia ixx="0.001" ixy="0" ixz="0" iyy="0.001" iyz="0" izz="0.001"/>
      </inertial>
      <visual name="visual_RightUpLeg">
        <origin xyz="0 0 0" rpy="0 0 0"/>
        <geometry>
          <mesh filename="RightUpLeg.stl" scale="1.0 1.0 1.0"/>
        </geometry>
        <material name="asdf1:Beta_HighLimbsGeoSG2"/>
      </visual>
      <collision name="collision_RightUpLeg">
        <origin xyz="-0.00037 0.00081 0.0003" rpy="0 0 0"/>
        <geometry>
          <sphere radius="0.08656"/>
        </geometry>
      </collision>
      <collision name="collision_RightUpLeg.1">
        <origin xyz="0 0 0" rpy="0 0 0"/>
        <geometry>
          <mesh filename="c_RightUpLeg.stl" scale="1.0 1.0 1.0"/>
        </geometry>
      </collision>
    </link>

    <link name="link_Spine">
      <inertial>
        <origin xyz="0 0 0" rpy="0 0 0"/>
        <mass value="5.5"/>
        <inertia ixx="0.001" ixy="0" ixz="0" iyy="0.001" iyz="0" izz="0.001"/>
      </inertial>
      <visual name="visual_Spine">
        <origin xyz="0 0 0" rpy="0 0 0"/>
        <geometry>
          <mesh filename="Spine.stl" scale="1.0 1.0 1.0"/>
        </geometry>
        <material name="Beta_Joints_MAT"/>
      </visual>
      <collision name="collision_Spine">
        <origin xyz="-0.00022 0.0197 -0.10448" rpy="0 0 0"/>
        <geometry>
          <sphere radius="0.12974"/>
        </geometry>
      </collision>
    </link>

    <link name="link_Spine1">
      <inertial>
        <origin xyz="0 0 0" rpy="0 0 0"/>
        <mass value="8.0"/>
        <inertia ixx="0.001" ixy="0" ixz="0" iyy="0.001" iyz="0" izz="0.001"/>
      </inertial>
      <visual name="visual_Spine1">
        <origin xyz="0 0 0" rpy="0 0 0"/>
        <geometry>
          <mesh filename="Spine1.stl" scale="1.0 1.0 1.0"/>
        </geometry>
        <material name="Beta_Joints_MAT"/>
      </visual>
      <collision name="collision_Spine1">
        <origin xyz="0 0 0" rpy="0 0 0"/>
        <geometry>
          <sphere radius="0.10869"/>
        </geometry>
      </collision>
    </link>

    <link name="link_Spine2">
      <inertial>
        <origin xyz="0 0 0" rpy="0 0 0"/>
        <mass value="8.0"/>
        <inertia ixx="0.001" ixy="0" ixz="0" iyy="0.001" iyz="0" izz="0.001"/>
      </inertial>
      <visual name="visual_Spine2">
        <origin xyz="0 0 0" rpy="0 0 0"/>
        <geometry>
          <mesh filename="Spine2.stl" scale="1.0 1.0 1.0"/>
        </geometry>
        <material name="asdf1:Beta_HighLimbsGeoSG2"/>
      </visual>
      <collision name="collision_Spine2">
        <origin xyz="0 0 0" rpy="0 0 0"/>
        <geometry>
          <mesh filename="c_Spine2.stl" scale="1.0 1.0 1.0"/>
        </geometry>
      </collision>
    </link>

    <joint name="link_Head" type="revolute">
      <origin xyz="7e-05 -0.01698 0.0968" rpy="1.5708 0 0"/>
      <parent link="link_Neck"/>
      <child link="link_Head"/>
      <axis xyz="0 1.0 0"/>
      <limit lower="-1.6" upper="1.6" effort="10.0" velocity="10.0"/>
    </joint>

    <joint name="link_LeftArm" type="spherical">
      <origin xyz="0.1055 0.02299 -0.00565" rpy="0 0 0"/>
      <parent link="link_LeftShoulder"/>
      <child link="link_LeftArm"/>
      <axis xyz = "0.000000 1.000000 0.000000" />
      <limit effort="1000.0" lower="-2" upper="2" velocity="10"/>
    </joint>

    <joint name="link_LeftFoot" type="revolute">
      <origin xyz="0 0.0304 -0.4433" rpy="0 0 0"/>
      <parent link="link_LeftLeg"/>
      <child link="link_LeftFoot"/>
      <limit effort="10.0" lower="-0.6" upper="0.4" velocity="10"/>
      <axis xyz="1 0 0"/>
    </joint>

    <joint name="link_LeftForeArm" type="revolute">
      <origin xyz="0.27874 1e-05 0" rpy="0 0 0"/>
      <parent link="link_LeftArm"/>
      <child link="link_LeftForeArm"/>
      <limit effort="1.0" lower="0" upper="2" velocity="10"/>
	  <axis xyz="0 0 1"/>
    </joint>

    <joint name="link_LeftHand" type="spherical">
      <origin xyz="0.28308 -0.0001 0" rpy="0 0 0"/>
      <parent link="link_LeftForeArm"/>
      <child link="link_LeftHand"/>
      <axis xyz="1 1 0"/>
    </joint>

    <joint name="link_LeftHandIndex1" type="revolute">
      <origin xyz="0.09078 -0.02254 -0.0049" rpy="0 0 0"/>
      <parent link="link_LeftHand"/>
      <child link="link_LeftHandIndex1"/>
      <limit effort="1.0" lower="0" upper="2" velocity="10"/>
	  <axis xyz="1 0 0"/>
    </joint>

    <joint name="link_LeftHandIndex2" type="revolute">
      <origin xyz="0.03621 -0.00028 0" rpy="0 0 0"/>
      <parent link="link_LeftHandIndex1"/>
      <child link="link_LeftHandIndex2"/>
      <limit effort="1.0" lower="0" upper="2" velocity="10"/>
	  <axis xyz="1 0 0"/>
    </joint>

    <joint name="link_LeftHandIndex3" type="revolute">
      <origin xyz="0.02964 0.00028 -0.0003" rpy="0 0 0"/>
      <parent link="link_LeftHandIndex2"/>
      <child link="link_LeftHandIndex3"/>
       <limit effort="1.0" lower="0" upper="2" velocity="10"/>
	  <axis xyz="1 0 0"/>
    </joint>

    <joint name="link_LeftHandMiddle1" type="revolute">
      <origin xyz="0.09542 0.00018 -0.00011" rpy="0 0 0"/>
      <parent link="link_LeftHand"/>
      <child link="link_LeftHandMiddle1"/>
      <limit effort="1.0" lower="0" upper="2" velocity="10"/>
	  <axis xyz="1 0 0"/>
    </joint>

    <joint name="link_LeftHandMiddle2" type="revolute">
      <origin xyz="0.03673 -0.00047 0" rpy="0 0 0"/>
      <parent link="link_LeftHandMiddle1"/>
      <child link="link_LeftHandMiddle2"/>
      <limit effort="1.0" lower="0" upper="2" velocity="10"/>
	  <axis xyz="1 0 0"/>
    </joint>

    <joint name="link_LeftHandMiddle3" type="revolute">
      <origin xyz="0.02993 0 0" rpy="0 0 0"/>
      <parent link="link_LeftHandMiddle2"/>
      <child link="link_LeftHandMiddle3"/>
      <limit effort="1.0" lower="0" upper="2" velocity="10"/>
	  <axis xyz="1 0 0"/>
    </joint>

    <joint name="link_LeftHandPinky1" type="revolute">
      <origin xyz="0.08091 0.03815 -0.00528" rpy="0 0 0"/>
      <parent link="link_LeftHand"/>
      <child link="link_LeftHandPinky1"/>
      <limit effort="1.0" lower="0" upper="2" velocity="10"/>
	  <axis xyz="1 0 0"/>
    </joint>

    <joint name="link_LeftHandPinky2" type="revolute">
      <origin xyz="0.03582 0 0.00038" rpy="0 0 0"/>
      <parent link="link_LeftHandPinky1"/>
      <child link="link_LeftHandPinky2"/>
      <limit effort="1.0" lower="0" upper="2" velocity="10"/>
	  <axis xyz="1 0 0"/>
    </joint>

    <joint name="link_LeftHandPinky3" type="revolute">
      <origin xyz="0.02092 0 -0.00038" rpy="0 0 0"/>
      <parent link="link_LeftHandPinky2"/>
      <child link="link_LeftHandPinky3"/>
      <limit effort="1.0" lower="0" upper="2" velocity="10"/>
	  <axis xyz="1 0 0"/>
    </joint>

    <joint name="link_LeftHandRing1" type="revolute">
      <origin xyz="0.09094 0.01855 -0.00038" rpy="0 0 0"/>
      <parent link="link_LeftHand"/>
      <child link="link_LeftHandRing1"/>
      <limit effort="1.0" lower="0" upper="2" velocity="10"/>
	  <axis xyz="1 0 0"/>
    </joint>

    <joint name="link_LeftHandRing2" type="revolute">
      <origin xyz="0.03149 0.00018 0" rpy="0 0 0"/>
      <parent link="link_LeftHandRing1"/>
      <child link="link_LeftHandRing2"/>
      <limit effort="1.0" lower="0" upper="2" velocity="10"/>
	  <axis xyz="1 0 0"/>
    </joint>

    <joint name="link_LeftHandRing3" type="revolute">
      <origin xyz="0.02939 0.0002 -0.00038" rpy="0 0 0"/>
      <parent link="link_LeftHandRing2"/>
      <child link="link_LeftHandRing3"/>
      <limit effort="1.0" lower="0" upper="2" velocity="10"/>
	  <axis xyz="1 0 0"/>
    </joint>

    <joint name="link_LeftHandThumb1" type="revolute">
      <origin xyz="0.02428 -0.02706 -0.01583" rpy="0 0 0"/>
      <parent link="link_LeftHand"/>
      <child link="link_LeftHandThumb1"/>
      <limit effort="1.0" lower="0" upper="2" velocity="10"/>
	  <axis xyz="0.5 0 0.5"/>
    </joint>

    <joint name="link_LeftHandThumb2" type="revolute">
      <origin xyz="0.03265 -0.01871 -0.01922" rpy="0 0 0"/>
      <parent link="link_LeftHandThumb1"/>
      <child link="link_LeftHandThumb2"/>
      <limit effort="1.0" lower="0" upper="2" velocity="10"/>
	  <axis xyz="0.5 0 0.5"/>
    </joint>

    <joint name="link_LeftHandThumb3" type="revolute">
      <origin xyz="0.02612 -0.01522 -0.01508" rpy="0 0 0"/>
      <parent link="link_LeftHandThumb2"/>
      <child link="link_LeftHandThumb3"/>
      <limit effort="1.0" lower="0" upper="2" velocity="10"/>
	  <axis xyz="0.5 0 0.5"/>
    </joint>

    <joint name="link_LeftLeg" type="revolute">
      <origin xyz="0 -0.00269 -0.44503" rpy="0 0 0"/>
      <parent link="link_LeftUpLeg"/>
      <child link="link_LeftLeg"/>
      <limit effort="10.0" lower="0" upper="2.5" velocity="10"/>
	  <axis xyz = "1.000000 0.000000 0.000000" />
    </joint>

    <joint name="link_LeftShoulder" type="fixed">
      <origin xyz="0.04625 0.02549 0.10964" rpy="0 0 0"/>
      <parent link="link_Spine2"/>
      <child link="link_LeftShoulder"/>
      <limit effort="1000.0" lower="0" upper="0.2" velocity="10"/>
	  <axis xyz = "0.000000 1.000000 0.000000" />
    </joint>

    <joint name="link_LeftToeBase" type="revolute">
      <origin xyz="0.00065 -0.10737 -0.06079" rpy="0 0 0"/>
      <parent link="link_LeftFoot"/>
      <child link="link_LeftToeBase"/>
      <limit effort="10.0" lower="-0.6" upper="0.6" velocity="10"/>
      <axis xyz = "1.000000 0.000000 0.000000" />
    </joint>

    <joint name="link_LeftUpLeg" type="spherical">
      <origin xyz="0.08245 0.01519 -0.06714" rpy="0 0 0"/>
      <parent link="link_Hips"/>
      <child link="link_LeftUpLeg"/>
      <limit effort="1000.0" lower="-.14" upper="1" velocity="10"/>
      <axis xyz = "1.000000 1.000000 1.000000" />
    </joint>

    <joint name="link_Neck" type="spherical">
      <origin xyz="0.00024 0.02511 0.16549" rpy="0 0 0"/>
      <parent link="link_Spine2"/>
      <child link="link_Neck"/>
      <limit effort="200.0" velocity="40.0"/>
      <axis xyz = "1.000000 1.000000 0.000000" />
    </joint>

    <joint name="link_RightArm" type="spherical">
      <origin xyz="-0.10656 0.02189 -0.00656" rpy="0 0 0"/>
      <parent link="link_RightShoulder"/>
      <child link="link_RightArm"/>
      <axis xyz = "0.000000 1.000000 0.000000" />
      <limit effort="1000.0" lower="-2" upper="2" velocity="10"/>
    </joint>

    <joint name="link_RightFoot" type="revolute">
      <origin xyz="-0.00065 0.03005 -0.44359" rpy="0 0 0"/>
      <parent link="link_RightLeg"/>
      <child link="link_RightFoot"/>
      <limit effort="10.0" lower="-0.6" upper="0.4" velocity="10"/>
      <axis xyz="1 0 0"/>
    </joint>

    <joint name="link_RightForeArm" type="revolute">
      <origin xyz="-0.2773 0 0.00236" rpy="0 0 0"/>
      <parent link="link_RightArm"/>
      <child link="link_RightForeArm"/>
      <limit effort="1.0" lower="0" upper="2" velocity="10"/>
      <axis xyz="0 0 1"/>
    </joint>

    <joint name="link_RightHand" type="spherical">
      <origin xyz="-0.2841 0 -0.00198" rpy="0 0 0"/>
      <parent link="link_RightForeArm"/>
      <child link="link_RightHand"/>
      <axis xyz="1 1 0"/>
    </joint>

    <joint name="link_RightHandIndex1" type="revolute">
      <origin xyz="-0.09108 -0.02257 -0.00555" rpy="0 0 0"/>
      <parent link="link_RightHand"/>
      <child link="link_RightHandIndex1"/>
      <limit effort="1.0" lower="0" upper="2" velocity="10"/>
	  <axis xyz="1 0 0"/>
    </joint>

    <joint name="link_RightHandIndex2" type="revolute">
      <origin xyz="-0.03691 0 0.00054" rpy="0 0 0"/>
      <parent link="link_RightHandIndex1"/>
      <child link="link_RightHandIndex2"/>
      <limit effort="1.0" lower="0" upper="2" velocity="10"/>
	  <axis xyz="1 0 0"/>
    </joint>

    <joint name="link_RightHandIndex3" type="revolute">
      <origin xyz="-0.02823 -5e-05 0.00027" rpy="0 0 0"/>
      <parent link="link_RightHandIndex2"/>
      <child link="link_RightHandIndex3"/>
      <limit effort="1.0" lower="0" upper="2" velocity="10"/>
	  <axis xyz="1 0 0"/>
    </joint>

    <joint name="link_RightHandMiddle1" type="revolute">
      <origin xyz="-0.09542 -5e-05 0.00011" rpy="0 0 0"/>
      <parent link="link_RightHand"/>
      <child link="link_RightHandMiddle1"/>
      <limit effort="1.0" lower="0" upper="2" velocity="10"/>
	  <axis xyz="1 0 0"/>
    </joint>

    <joint name="link_RightHandMiddle2" type="revolute">
      <origin xyz="-0.03677 0 0" rpy="0 0 0"/>
      <parent link="link_RightHandMiddle1"/>
      <child link="link_RightHandMiddle2"/>
      <limit effort="1.0" lower="0" upper="2" velocity="10"/>
	  <axis xyz="1 0 0"/>
    </joint>

    <joint name="link_RightHandMiddle3" type="revolute">
      <origin xyz="-0.02945 0 -0.00023" rpy="0 0 0"/>
      <parent link="link_RightHandMiddle2"/>
      <child link="link_RightHandMiddle3"/>
      <limit effort="1.0" lower="0" upper="2" velocity="10"/>
	  <axis xyz="1 0 0"/>
    </joint>

    <joint name="link_RightHandPinky1" type="revolute">
      <origin xyz="-0.08131 0.03814 -0.00471" rpy="0 0 0"/>
      <parent link="link_RightHand"/>
      <child link="link_RightHandPinky1"/>
      <limit effort="1.0" lower="0" upper="2" velocity="10"/>
	  <axis xyz="1 0 0"/>
    </joint>

    <joint name="link_RightHandPinky2" type="revolute">
      <origin xyz="-0.03544 0 9e-05" rpy="0 0 0"/>
      <parent link="link_RightHandPinky1"/>
      <child link="link_RightHandPinky2"/>
      <limit effort="1.0" lower="0" upper="2" velocity="10"/>
	  <axis xyz="1 0 0"/>
    </joint>

    <joint name="link_RightHandPinky3" type="revolute">
      <origin xyz="-0.02094 0 -0.00026" rpy="0 0 0"/>
      <parent link="link_RightHandPinky2"/>
      <child link="link_RightHandPinky3"/>
      <limit effort="1.0" lower="0" upper="2" velocity="10"/>
	  <axis xyz="1 0 0"/>
    </joint>

    <joint name="link_RightHandRing1" type="revolute">
      <origin xyz="-0.0911 0.01826 -0.00061" rpy="0 0 0"/>
      <parent link="link_RightHand"/>
      <child link="link_RightHandRing1"/>
      <limit effort="1.0" lower="0" upper="2" velocity="10"/>
	  <axis xyz="1 0 0"/>
    </joint>

    <joint name="link_RightHandRing2" type="revolute">
      <origin xyz="-0.03141 0.00031 0.00031" rpy="0 0 0"/>
      <parent link="link_RightHandRing1"/>
      <child link="link_RightHandRing2"/>
      <limit effort="1.0" lower="0" upper="2" velocity="10"/>
	  <axis xyz="1 0 0"/>
    </joint>

    <joint name="link_RightHandRing3" type="revolute">
      <origin xyz="-0.02942 0.00031 0" rpy="0 0 0"/>
      <parent link="link_RightHandRing2"/>
      <child link="link_RightHandRing3"/>
      <limit effort="1.0" lower="0" upper="2" velocity="10"/>
	  <axis xyz="1 0 0"/>
    </joint>

    <joint name="link_RightHandThumb1" type="spherical">
      <origin xyz="-0.02453 -0.02682 -0.01574" rpy="0 0 0"/>
      <parent link="link_RightHand"/>
      <child link="link_RightHandThumb1"/>
    </joint>

    <joint name="link_RightHandThumb2" type="revolute">
      <origin xyz="-0.03242 -0.01872 -0.01836" rpy="0 0 0"/>
      <parent link="link_RightHandThumb1"/>
      <child link="link_RightHandThumb2"/>
      <limit effort="1.0" lower="0" upper="2" velocity="10"/>
	  <axis xyz="0.5 0 0.5"/>
    </joint>

    <joint name="link_RightHandThumb3" type="revolute">
      <origin xyz="-0.02676 -0.01543 -0.01549" rpy="0 0 0"/>
      <parent link="link_RightHandThumb2"/>
      <child link="link_RightHandThumb3"/>
      <limit effort="1.0" lower="0" upper="2" velocity="10"/>
	  <axis xyz="0.5 0 0.5"/>
    </joint>

    <joint name="link_RightLeg" type="revolute">
      <origin xyz="0.00065 -0.00196 -0.44457" rpy="0 0 0"/>
      <parent link="link_RightUpLeg"/>
      <child link="link_RightLeg"/>
	  <limit effort="10.0" lower="0" upper="2.5" velocity="10"/>
	  <axis xyz = "1.000000 0.000000 0.000000" />
    </joint>

    <joint name="link_RightShoulder" type="fixed">
      <origin xyz="-0.04536 0.02663 0.10998" rpy="0 0 0"/>
      <parent link="link_Spine2"/>
      <child link="link_RightShoulder"/>
      <limit effort="1000.0" lower="0" upper="0.2" velocity="10"/>
	  <axis xyz = "0.000000 1.000000 0.000000" />
    </joint>

    <joint name="link_RightToeBase" type="revolute">
      <origin xyz="0 -0.11037 -0.06152" rpy="0 0 0"/>
      <parent link="link_RightFoot"/>
      <child link="link_RightToeBase"/>
      <limit effort="10.0" lower="-0.6" upper="0.6" velocity="10"/>
      <axis xyz = "1.000000 0.000000 0.000000" />
    </joint>

    <joint name="link_RightUpLeg" type="spherical">
      <origin xyz="-0.08209 0.01519 -0.06714" rpy="0 0 0"/>
      <parent link="link_Hips"/>
      <child link="link_RightUpLeg"/>
      <limit effort="1000.0" lower="-.14" upper="1" velocity="10"/>
      <axis xyz = "1.000000 1.000000 1.000000" />
    </joint>

    <joint name="link_Spine" type="fixed">
      <origin xyz="0.00037 -0.00172 0.10244" rpy="0 0 0"/>
      <parent link="link_Hips"/>
      <child link="link_Spine"/>
    </joint>

    <joint name="link_Spine1" type="spherical">
      <origin xyz="-0.00026 0.01027 0.10076" rpy="0 0 0"/>
      <parent link="link_Spine"/>
      <child link="link_Spine1"/>
      <limit effort="10.0" velocity="10.0"/>
      <axis xyz = "1.000000 1.000000 1.000000" />
    </joint>

    <joint name="link_Spine2" type="spherical">
      <origin xyz="0 0.01405 0.09109" rpy="0 0 0"/>
      <parent link="link_Spine1"/>
      <child link="link_Spine2"/>
      <limit effort="10.0" velocity="10.0"/>
      <axis xyz = "1.000000 1.000000 1.000000" />
    </joint>

    <material name="Beta_Joints_MAT">
      <color rgba="0.26667 0.09962 0.08081 1.0"/>
    </material>

    <material name="asdf1:Beta_HighLimbsGeoSG2">
      <color rgba="0.6696 0.24185 0.21092 1.0"/>
    </material>

  </robot>
